Workbook

Sheet Sheet1
F1: =IF([1]Sheet1!A1="","",[1]Sheet1!A1) -> name | G1: =IF([1]Sheet1!B1="","",[1]Sheet1!B1) -> IMK Triwulanan 2025 - PENCACAHAN | H1: =IF([1]Sheet1!C1="","",[1]Sheet1!C1) | I1: =IF([1]Sheet1!D1="","",[1]Sheet1!D1) | J1: =IF([1]Sheet1!E1="","",[1]Sheet1!E1) | K1: =IF([1]Sheet1!F1="","",[1]Sheet1!F1) -> PENDATAAN IBS TRIWULANAN 2025 | O1: =IF([1]Sheet1!J1="","",[1]Sheet1!J1) | S1: =IF([1]Sheet1!N1="","",[1]Sheet1!N1) | W1: =IF([1]Sheet1!R1="","",[1]Sheet1!R1) | X1: =IF([1]Sheet1!S1="","",[1]Sheet1!S1) | Y1: =IF([1]Sheet1!T1="","",[1]Sheet1!T1) | Z1: =IF([1]Sheet1!U1="","",[1]Sheet1!U1) | AA1: =IF([1]Sheet1!V1="","",[1]Sheet1!V1) | AB1: =IF([1]Sheet1!W1="","",[1]Sheet1!W1) | AC1: =IF([1]Sheet1!X1="","",[1]Sheet1!X1) | AD1: =IF([1]Sheet1!Y1="","",[1]Sheet1!Y1) | ... AI1: =IF([1]Sheet1!AD1="","",[1]Sheet1!AD1) | AM1: =IF([1]Sheet1!AH1="","",[1]Sheet1!AH1) | AQ1: =IF([1]Sheet1!AL1="","",[1]Sheet1!AL1) | AR1: =IF([1]Sheet1!AM1="","",[1]Sheet1!AM1) | AS1: =IF([1]Sheet1!AN1="","",[1]Sheet1!AN1)
A2: weights | B2: % lapangan | C2: %lapangan_weighted | D2: total_belum | E2: kota | F2: =IF([1]Sheet1!A2="","",[1]Sheet1!A2) | G2: =IF([1]Sheet1!B2="","",[1]Sheet1!B2) -> total | H2: =IF([1]Sheet1!C2="","",[1]Sheet1!C2) -> cacah | I2: =IF([1]Sheet1!D2="","",[1]Sheet1!D2) -> selesai | J2: =IF([1]Sheet1!E2="","",[1]Sheet1!E2) -> pct_selesai | K2: =IF([1]Sheet1!F2="","",[1]Sheet1!F2) -> total | L2: =IF([1]Sheet1!G2="","",[1]Sheet1!G2) -> cacah | M2: =IF([1]Sheet1!H2="","",[1]Sheet1!H2) -> selesai | ... AS2: =IF([1]Sheet1!AN2="","",[1]Sheet1!AN2)
F3: =IF([1]Sheet1!A3="","",[1]Sheet1!A3) -> kd_kab | G3: =IF([1]Sheet1!B3="","",[1]Sheet1!B3) | H3: =IF([1]Sheet1!C3="","",[1]Sheet1!C3) | I3: =IF([1]Sheet1!D3="","",[1]Sheet1!D3) | J3: =IF([1]Sheet1!E3="","",[1]Sheet1!E3) | K3: =IF([1]Sheet1!F3="","",[1]Sheet1!F3) | L3: =IF([1]Sheet1!G3="","",[1]Sheet1!G3) | M3: =IF([1]Sheet1!H3="","",[1]Sheet1!H3) | ... AS3: =IF([1]Sheet1!AN3="","",[1]Sheet1!AN3)
F4: =IF([1]Sheet1!A4="","",[1]Sheet1!A4) -> 9403 | G4: =IF([1]Sheet1!B4="","",[1]Sheet1!B4) -> 16 | H4: =IF([1]Sheet1!C4="","",[1]Sheet1!C4) -> 0 | I4: =IF([1]Sheet1!D4="","",[1]Sheet1!D4) -> 16 | J4: =IF([1]Sheet1!E4="","",[1]Sheet1!E4) -> 1 | K4: =IF([1]Sheet1!F4="","",[1]Sheet1!F4) -> 6 | L4: =IF([1]Sheet1!G4="","",[1]Sheet1!G4) -> 0 | M4: =IF([1]Sheet1!H4="","",[1]Sheet1!H4) -> 6 | ... AS4: =IF([1]Sheet1!AN4="","",[1]Sheet1!AN4)
F5: =IF([1]Sheet1!A5="","",[1]Sheet1!A5) -> 9408 | G5: =IF([1]Sheet1!B5="","",[1]Sheet1!B5) -> 41 | H5: =IF([1]Sheet1!C5="","",[1]Sheet1!C5) -> 0 | I5: =IF([1]Sheet1!D5="","",[1]Sheet1!D5) -> 41 | J5: =IF([1]Sheet1!E5="","",[1]Sheet1!E5) -> 1 | K5: =IF([1]Sheet1!F5="","",[1]Sheet1!F5) -> 3 | L5: =IF([1]Sheet1!G5="","",[1]Sheet1!G5) -> 0 | M5: =IF([1]Sheet1!H5="","",[1]Sheet1!H5) -> 3 | ... AS5: =IF([1]Sheet1!AN5="","",[1]Sheet1!AN5)
F6: =IF([1]Sheet1!A6="","",[1]Sheet1!A6) -> 9409 | G6: =IF([1]Sheet1!B6="","",[1]Sheet1!B6) -> 28 | H6: =IF([1]Sheet1!C6="","",[1]Sheet1!C6) -> 0 | I6: =IF([1]Sheet1!D6="","",[1]Sheet1!D6) -> 33 | J6: =IF([1]Sheet1!E6="","",[1]Sheet1!E6) -> 1.18 | K6: =IF([1]Sheet1!F6="","",[1]Sheet1!F6) -> 5 | L6: =IF([1]Sheet1!G6="","",[1]Sheet1!G6) -> 0 | M6: =IF([1]Sheet1!H6="","",[1]Sheet1!H6) -> 5 | ... AS6: =IF([1]Sheet1!AN6="","",[1]Sheet1!AN6)
F7: =IF([1]Sheet1!A7="","",[1]Sheet1!A7) -> 9419 | G7: =IF([1]Sheet1!B7="","",[1]Sheet1!B7) -> 50 | H7: =IF([1]Sheet1!C7="","",[1]Sheet1!C7) -> 0 | I7: =IF([1]Sheet1!D7="","",[1]Sheet1!D7) -> 50 | J7: =IF([1]Sheet1!E7="","",[1]Sheet1!E7) -> 1 | K7: =IF([1]Sheet1!F7="","",[1]Sheet1!F7) | L7: =IF([1]Sheet1!G7="","",[1]Sheet1!G7) | M7: =IF([1]Sheet1!H7="","",[1]Sheet1!H7) | ... AS7: =IF([1]Sheet1!AN7="","",[1]Sheet1!AN7)
F8: =IF([1]Sheet1!A8="","",[1]Sheet1!A8) -> 9420 | G8: =IF([1]Sheet1!B8="","",[1]Sheet1!B8) -> 33 | H8: =IF([1]Sheet1!C8="","",[1]Sheet1!C8) -> 0 | I8: =IF([1]Sheet1!D8="","",[1]Sheet1!D8) -> 33 | J8: =IF([1]Sheet1!E8="","",[1]Sheet1!E8) -> 1 | K8: =IF([1]Sheet1!F8="","",[1]Sheet1!F8) | L8: =IF([1]Sheet1!G8="","",[1]Sheet1!G8) | M8: =IF([1]Sheet1!H8="","",[1]Sheet1!H8) | ... AS8: =IF([1]Sheet1!AN8="","",[1]Sheet1!AN8)
F9: =IF([1]Sheet1!A9="","",[1]Sheet1!A9) -> 9426 | G9: =IF([1]Sheet1!B9="","",[1]Sheet1!B9) -> 10 | H9: =IF([1]Sheet1!C9="","",[1]Sheet1!C9) -> 0 | I9: =IF([1]Sheet1!D9="","",[1]Sheet1!D9) -> 10 | J9: =IF([1]Sheet1!E9="","",[1]Sheet1!E9) -> 1 | K9: =IF([1]Sheet1!F9="","",[1]Sheet1!F9) | L9: =IF([1]Sheet1!G9="","",[1]Sheet1!G9) | M9: =IF([1]Sheet1!H9="","",[1]Sheet1!H9) | ... AS9: =IF([1]Sheet1!AN9="","",[1]Sheet1!AN9)
F10: =IF([1]Sheet1!A10="","",[1]Sheet1!A10) -> 9427 | G10: =IF([1]Sheet1!B10="","",[1]Sheet1!B10) -> 29 | H10: =IF([1]Sheet1!C10="","",[1]Sheet1!C10) -> 0 | I10: =IF([1]Sheet1!D10="","",[1]Sheet1!D10) -> 29 | J10: =IF([1]Sheet1!E10="","",[1]Sheet1!E10) -> 1 | K10: =IF([1]Sheet1!F10="","",[1]Sheet1!F10) | L10: =IF([1]Sheet1!G10="","",[1]Sheet1!G10) | M10: =IF([1]Sheet1!H10="","",[1]Sheet1!H10) | ... AS10: =IF([1]Sheet1!AN10="","",[1]Sheet1!AN10)
F11: =IF([1]Sheet1!A11="","",[1]Sheet1!A11) -> 9428 | G11: =IF([1]Sheet1!B11="","",[1]Sheet1!B11) -> 5 | H11: =IF([1]Sheet1!C11="","",[1]Sheet1!C11) -> 0 | I11: =IF([1]Sheet1!D11="","",[1]Sheet1!D11) -> 5 | J11: =IF([1]Sheet1!E11="","",[1]Sheet1!E11) -> 1 | K11: =IF([1]Sheet1!F11="","",[1]Sheet1!F11) | L11: =IF([1]Sheet1!G11="","",[1]Sheet1!G11) | M11: =IF([1]Sheet1!H11="","",[1]Sheet1!H11) | ... AS11: =IF([1]Sheet1!AN11="","",[1]Sheet1!AN11)
F12: =IF([1]Sheet1!A12="","",[1]Sheet1!A12) -> 9471 | G12: =IF([1]Sheet1!B12="","",[1]Sheet1!B12) -> 95 | H12: =IF([1]Sheet1!C12="","",[1]Sheet1!C12) -> 0 | I12: =IF([1]Sheet1!D12="","",[1]Sheet1!D12) -> 96 | J12: =IF([1]Sheet1!E12="","",[1]Sheet1!E12) -> 1.01 | K12: =IF([1]Sheet1!F12="","",[1]Sheet1!F12) -> 44 | L12: =IF([1]Sheet1!G12="","",[1]Sheet1!G12) -> 0 | M12: =IF([1]Sheet1!H12="","",[1]Sheet1!H12) -> 44 | ... AS12: =IF([1]Sheet1!AN12="","",[1]Sheet1!AN12)
F13: =IF([1]Sheet1!A13="","",[1]Sheet1!A13) -> 9501 | G13: =IF([1]Sheet1!B13="","",[1]Sheet1!B13) -> 203 | H13: =IF([1]Sheet1!C13="","",[1]Sheet1!C13) -> 0 | I13: =IF([1]Sheet1!D13="","",[1]Sheet1!D13) -> 202 | J13: =IF([1]Sheet1!E13="","",[1]Sheet1!E13) -> 1 | K13: =IF([1]Sheet1!F13="","",[1]Sheet1!F13) -> 14 | L13: =IF([1]Sheet1!G13="","",[1]Sheet1!G13) -> 0 | M13: =IF([1]Sheet1!H13="","",[1]Sheet1!H13) -> 14 | ... AS13: =IF([1]Sheet1!AN13="","",[1]Sheet1!AN13)
F14: =IF([1]Sheet1!A14="","",[1]Sheet1!A14) -> 9502 | G14: =IF([1]Sheet1!B14="","",[1]Sheet1!B14) -> 58 | H14: =IF([1]Sheet1!C14="","",[1]Sheet1!C14) -> 0 | I14: =IF([1]Sheet1!D14="","",[1]Sheet1!D14) -> 58 | J14: =IF([1]Sheet1!E14="","",[1]Sheet1!E14) -> 1 | K14: =IF([1]Sheet1!F14="","",[1]Sheet1!F14) -> 4 | L14: =IF([1]Sheet1!G14="","",[1]Sheet1!G14) -> 0 | M14: =IF([1]Sheet1!H14="","",[1]Sheet1!H14) -> 2 | ... AS14: =IF([1]Sheet1!AN14="","",[1]Sheet1!AN14)
... F24: =IF([1]Sheet1!A24="","",[1]Sheet1!A24) | G24: =IF([1]Sheet1!B24="","",[1]Sheet1!B24) | H24: =IF([1]Sheet1!C24="","",[1]Sheet1!C24) | I24: =IF([1]Sheet1!D24="","",[1]Sheet1!D24) | J24: =IF([1]Sheet1!E24="","",[1]Sheet1!E24) | K24: =IF([1]Sheet1!F24="","",[1]Sheet1!F24) | L24: =IF([1]Sheet1!G24="","",[1]Sheet1!G24) | M24: =IF([1]Sheet1!H24="","",[1]Sheet1!H24) | ... AS24: =IF([1]Sheet1!AN24="","",[1]Sheet1!AN24)
A25: =SUM(A29:A60) -> 1 | B25: =SUM(B29:B60) -> 18.995074 | C25: =SUM(C29:C60) -> 0.99893617 | D25: =SUM(D29:D60) -> 0.0010638298 | F25: =IF([1]Sheet1!A25="","",[1]Sheet1!A25) | G25: =SUM(G28:G60) -> 940 | H25: =SUM(H28:H60) -> 0 | I25: =SUM(I28:I60) -> 939 | J25: =SUM(H25:I25)/G25 -> 0.99893617 | K25: =SUM(K28:K60) -> 130 | L25: =SUM(L28:L60) -> 4 | M25: =SUM(M28:M60) -> 121 | N25: =SUM(L25:M25)/K25 -> 0.96153846 | O25: =SUM(O28:O60) -> 0 | P25: =SUM(P28:P60) -> 0 | Q25: =SUM(Q28:Q60) -> 0 | R25: =SUM(P25:Q25)/O25 -> #DIV/0! | S25: =SUM(S28:S60) -> 0 | T25: =SUM(T28:T60) -> 0 | U25: =SUM(U28:U60) -> 0 | V25: =SUM(T25:U25)/S25 -> #DIV/0! | W25: =SUM(W28:W60) -> 0 | X25: =SUM(X28:X60) -> 0 | Y25: =SUM(Y28:Y60) -> 0 | Z25: =SUM(X25:Y25)/W25 -> #DIV/0! | AA25: =IF([1]Sheet1!V25="","",[1]Sheet1!V25) | AB25: =IF([1]Sheet1!W25="","",[1]Sheet1!W25) | AC25: =IF([1]Sheet1!X25="","",[1]Sheet1!X25) | AD25: =IF([1]Sheet1!Y25="","",[1]Sheet1!Y25) | AE25: =IF([1]Sheet1!Z25="","",[1]Sheet1!Z25) | AF25: =IF([1]Sheet1!AA25="","",[1]Sheet1!AA25) | AG25: =IF([1]Sheet1!AB25="","",[1]Sheet1!AB25) | AH25: =IF([1]Sheet1!AC25="","",[1]Sheet1!AC25) | AI25: =SUM(AI28:AI60) -> 0 | AJ25: =SUM(AJ28:AJ60) -> 0 | AK25: =SUM(AK28:AK60) -> 0 | AL25: =SUM(AJ25:AK25)/AI25 -> #DIV/0! | AM25: =SUM(AM28:AM60) -> 0 | AN25: =SUM(AN28:AN60) -> 0 | AO25: =SUM(AO28:AO60) -> 0 | AP25: =SUM(AN25:AO25)/AM25 -> #DIV/0! | AQ25: =IF([1]Sheet1!AL25="","",[1]Sheet1!AL25) | AR25: =IF([1]Sheet1!AM25="","",[1]Sheet1!AM25) | AS25: =IF([1]Sheet1!AN25="","",[1]Sheet1!AN25)
G27: 2 | H27: 3 | I27: 4 | J27: 5 | K27: 6 | L27: 7 | M27: 8 | N27: 9 | O27: 10 | P27: 11 | Q27: 12 | R27: 13 | S27: 14 | T27: 15 | U27: 16 | V27: 17 | W27: 18 | X27: 19 | Y27: 20 | Z27: 21 | AA27: 22 | AB27: 23 | AC27: 24 | AD27: 25 | AE27: 26 | AF27: 27 | AG27: 28 | AH27: 29 | AI27: 30 | AJ27: 31 | AK27: 32 | AL27: 33 | AM27: 34 | AN27: 35 | AO27: 36 | AP27: 37
F28: 9400 | G28: =IFERROR(IF(VLOOKUP($F28,$F$4:$AP$27,G$27,FALSE)="","",VLOOKUP($F28,$F$4:$AP$27,G$27,FALSE)),"") | H28: =IFERROR(IF(VLOOKUP($F28,$F$4:$AP$27,H$27,FALSE)="","",VLOOKUP($F28,$F$4:$AP$27,H$27,FALSE)),"") | I28: =IFERROR(IF(VLOOKUP($F28,$F$4:$AP$27,I$27,FALSE)="","",VLOOKUP($F28,$F$4:$AP$27,I$27,FALSE)),"") | J28: =IFERROR(IF(VLOOKUP($F28,$F$4:$AP$27,J$27,FALSE)="","",VLOOKUP($F28,$F$4:$AP$27,J$27,FALSE)),"") | K28: =IFERROR(IF(VLOOKUP($F28,$F$4:$AP$27,K$27,FALSE)="","",VLOOKUP($F28,$F$4:$AP$27,K$27,FALSE)),"") | L28: =IFERROR(IF(VLOOKUP($F28,$F$4:$AP$27,L$27,FALSE)="","",VLOOKUP($F28,$F$4:$AP$27,L$27,FALSE)),"") | M28: =IFERROR(IF(VLOOKUP($F28,$F$4:$AP$27,M$27,FALSE)="","",VLOOKUP($F28,$F$4:$AP$27,M$27,FALSE)),"") | N28: =IFERROR(IF(VLOOKUP($F28,$F$4:$AP$27,N$27,FALSE)="","",VLOOKUP($F28,$F$4:$AP$27,N$27,FALSE)),"") | ... Q28: =IFERROR(IF(VLOOKUP($F28,$F$4:$AP$27,Q$27,FALSE)="","",VLOOKUP($F28,$F$4:$AP$27,Q$27,FALSE)),"") | S28: =IFERROR(IF(VLOOKUP($F28,$F$4:$AP$27,S$27,FALSE)="","",VLOOKUP($F28,$F$4:$AP$27,S$27,FALSE)),"") | T28: =IFERROR(IF(VLOOKUP($F28,$F$4:$AP$27,T$27,FALSE)="","",VLOOKUP($F28,$F$4:$AP$27,T$27,FALSE)),"") | U28: =IFERROR(IF(VLOOKUP($F28,$F$4:$AP$27,U$27,FALSE)="","",VLOOKUP($F28,$F$4:$AP$27,U$27,FALSE)),"") | V28: =IFERROR(IF(VLOOKUP($F28,$F$4:$AP$27,V$27,FALSE)="","",VLOOKUP($F28,$F$4:$AP$27,V$27,FALSE)),"") | W28: =IFERROR(IF(VLOOKUP($F28,$F$4:$AP$27,W$27,FALSE)="","",VLOOKUP($F28,$F$4:$AP$27,W$27,FALSE)),"") | X28: =IFERROR(IF(VLOOKUP($F28,$F$4:$AP$27,X$27,FALSE)="","",VLOOKUP($F28,$F$4:$AP$27,X$27,FALSE)),"") | Y28: =IFERROR(IF(VLOOKUP($F28,$F$4:$AP$27,Y$27,FALSE)="","",VLOOKUP($F28,$F$4:$AP$27,Y$27,FALSE)),"") | Z28: =IFERROR(IF(VLOOKUP($F28,$F$4:$AP$27,Z$27,FALSE)="","",VLOOKUP($F28,$F$4:$AP$27,Z$27,FALSE)),"") | ... AG28: =IFERROR(IF(VLOOKUP($F28,$F$4:$AP$27,AG$27,FALSE)="","",VLOOKUP($F28,$F$4:$AP$27,AG$27,FALSE)),"")
A29: =IFERROR(G29/$G$25,"") -> 0.017021277 | B29: =IFERROR( IF(SUM(H29:I29)/G29>1,1,SUM(H29:I29)/G29),"") -> 1 | C29: =IFERROR(A29*B29,"") -> 0.017021277 | D29: =IFERROR(A29-C29,"") -> 0 | E29: =VLOOKUP(_xlfn.NUMBERVALUE(F29),Sheet2!$A$1:$B$29,2,FALSE) -> Kabupaten Jayapura | F29: 9403 | G29: =IFERROR(IF(VLOOKUP($F29,$F$4:$AP$27,G$27,FALSE)="","",VLOOKUP($F29,$F$4:$AP$27,G$27,FALSE)),"") -> 16 | H29: =IFERROR(IF(VLOOKUP($F29,$F$4:$AP$27,H$27,FALSE)="","",VLOOKUP($F29,$F$4:$AP$27,H$27,FALSE)),"") -> 0 | I29: =IF(IFERROR(IF(VLOOKUP($F29,$F$4:$AP$27,I$27,FALSE)="","",VLOOKUP($F29,$F$4:$AP$27,I$27,FALSE)),"")>G29,G29,IFERROR(IF(VLOOKUP($F29,$F$4:$AP$27,I$27,FALSE)="","",VLOOKUP($F29,$F$4:$AP$27,I$27,FALSE)),"")) -> 16 | J29: =IFERROR(IF(VLOOKUP($F29,$F$4:$AP$27,J$27,FALSE)="","",VLOOKUP($F29,$F$4:$AP$27,J$27,FALSE)),"") -> 1 | K29: =IFERROR(IF(VLOOKUP($F29,$F$4:$AP$27,K$27,FALSE)="","",VLOOKUP($F29,$F$4:$AP$27,K$27,FALSE)),"") -> 6 | L29: =IFERROR(IF(VLOOKUP($F29,$F$4:$AP$27,L$27,FALSE)="","",VLOOKUP($F29,$F$4:$AP$27,L$27,FALSE)),"") -> 0 | M29: =IF(IFERROR(IF(VLOOKUP($F29,$F$4:$AP$27,M$27,FALSE)="","",VLOOKUP($F29,$F$4:$AP$27,M$27,FALSE)),"")>K29,K29,IFERROR(IF(VLOOKUP($F29,$F$4:$AP$27,M$27,FALSE)="","",VLOOKUP($F29,$F$4:$AP$27,M$27,FALSE)),"")) -> 6 | N29: =IFERROR(IF(VLOOKUP($F29,$F$4:$AP$27,N$27,FALSE)="","",VLOOKUP($F29,$F$4:$AP$27,N$27,FALSE)),"") -> 1 | O29: =IFERROR(IF(VLOOKUP($F29,$F$4:$AP$27,O$27,FALSE)="","",VLOOKUP($F29,$F$4:$AP$27,O$27,FALSE)),"") | P29: =IFERROR(IF(VLOOKUP($F29,$F$4:$AP$27,P$27,FALSE)="","",VLOOKUP($F29,$F$4:$AP$27,P$27,FALSE)),"") | Q29: =IFERROR(IF(VLOOKUP($F29,$F$4:$AP$27,Q$27,FALSE)="","",VLOOKUP($F29,$F$4:$AP$27,Q$27,FALSE)),"") | R29: =IFERROR(IF(VLOOKUP($F29,$F$4:$AP$27,R$27,FALSE)="","",VLOOKUP($F29,$F$4:$AP$27,R$27,FALSE)),"") | S29: =IFERROR(IF(VLOOKUP($F29,$F$4:$AP$27,S$27,FALSE)="","",VLOOKUP($F29,$F$4:$AP$27,S$27,FALSE)),"") | T29: =IFERROR(IF(VLOOKUP($F29,$F$4:$AP$27,T$27,FALSE)="","",VLOOKUP($F29,$F$4:$AP$27,T$27,FALSE)),"") | U29: =IFERROR(IF(VLOOKUP($F29,$F$4:$AP$27,U$27,FALSE)="","",VLOOKUP($F29,$F$4:$AP$27,U$27,FALSE)),"") | ... AP29: =IFERROR(IF(VLOOKUP($F29,$F$4:$AP$27,AP$27,FALSE)="","",VLOOKUP($F29,$F$4:$AP$27,AP$27,FALSE)),"")
A30: =IFERROR(G30/$G$25,"") -> 0.043617021 | B30: =IFERROR( IF(SUM(H30:I30)/G30>1,1,SUM(H30:I30)/G30),"") -> 1 | C30: =IFERROR(A30*B30,"") -> 0.043617021 | D30: =IFERROR(A30-C30,"") -> 0 | E30: =VLOOKUP(_xlfn.NUMBERVALUE(F30),Sheet2!$A$1:$B$29,2,FALSE) -> Kepulauan Yapen | F30: 9408 | G30: =IFERROR(IF(VLOOKUP($F30,$F$4:$AP$27,G$27,FALSE)="","",VLOOKUP($F30,$F$4:$AP$27,G$27,FALSE)),"") -> 41 | H30: =IFERROR(IF(VLOOKUP($F30,$F$4:$AP$27,H$27,FALSE)="","",VLOOKUP($F30,$F$4:$AP$27,H$27,FALSE)),"") -> 0 | I30: =IF(IFERROR(IF(VLOOKUP($F30,$F$4:$AP$27,I$27,FALSE)="","",VLOOKUP($F30,$F$4:$AP$27,I$27,FALSE)),"")>G30,G30,IFERROR(IF(VLOOKUP($F30,$F$4:$AP$27,I$27,FALSE)="","",VLOOKUP($F30,$F$4:$AP$27,I$27,FALSE)),"")) -> 41 | J30: =IFERROR(IF(VLOOKUP($F30,$F$4:$AP$27,J$27,FALSE)="","",VLOOKUP($F30,$F$4:$AP$27,J$27,FALSE)),"") -> 1 | K30: =IFERROR(IF(VLOOKUP($F30,$F$4:$AP$27,K$27,FALSE)="","",VLOOKUP($F30,$F$4:$AP$27,K$27,FALSE)),"") -> 3 | L30: =IFERROR(IF(VLOOKUP($F30,$F$4:$AP$27,L$27,FALSE)="","",VLOOKUP($F30,$F$4:$AP$27,L$27,FALSE)),"") -> 0 | M30: =IF(IFERROR(IF(VLOOKUP($F30,$F$4:$AP$27,M$27,FALSE)="","",VLOOKUP($F30,$F$4:$AP$27,M$27,FALSE)),"")>K30,K30,IFERROR(IF(VLOOKUP($F30,$F$4:$AP$27,M$27,FALSE)="","",VLOOKUP($F30,$F$4:$AP$27,M$27,FALSE)),"")) -> 3 | N30: =IFERROR(IF(VLOOKUP($F30,$F$4:$AP$27,N$27,FALSE)="","",VLOOKUP($F30,$F$4:$AP$27,N$27,FALSE)),"") -> 1 | O30: =IFERROR(IF(VLOOKUP($F30,$F$4:$AP$27,O$27,FALSE)="","",VLOOKUP($F30,$F$4:$AP$27,O$27,FALSE)),"") | P30: =IFERROR(IF(VLOOKUP($F30,$F$4:$AP$27,P$27,FALSE)="","",VLOOKUP($F30,$F$4:$AP$27,P$27,FALSE)),"") | Q30: =IFERROR(IF(VLOOKUP($F30,$F$4:$AP$27,Q$27,FALSE)="","",VLOOKUP($F30,$F$4:$AP$27,Q$27,FALSE)),"") | R30: =IFERROR(IF(VLOOKUP($F30,$F$4:$AP$27,R$27,FALSE)="","",VLOOKUP($F30,$F$4:$AP$27,R$27,FALSE)),"") | S30: =IFERROR(IF(VLOOKUP($F30,$F$4:$AP$27,S$27,FALSE)="","",VLOOKUP($F30,$F$4:$AP$27,S$27,FALSE)),"") | T30: =IFERROR(IF(VLOOKUP($F30,$F$4:$AP$27,T$27,FALSE)="","",VLOOKUP($F30,$F$4:$AP$27,T$27,FALSE)),"") | U30: =IFERROR(IF(VLOOKUP($F30,$F$4:$AP$27,U$27,FALSE)="","",VLOOKUP($F30,$F$4:$AP$27,U$27,FALSE)),"") | ... AP30: =IFERROR(IF(VLOOKUP($F30,$F$4:$AP$27,AP$27,FALSE)="","",VLOOKUP($F30,$F$4:$AP$27,AP$27,FALSE)),"")
A31: =IFERROR(G31/$G$25,"") -> 0.029787234 | B31: =IFERROR( IF(SUM(H31:I31)/G31>1,1,SUM(H31:I31)/G31),"") -> 1 | C31: =IFERROR(A31*B31,"") -> 0.029787234 | D31: =IFERROR(A31-C31,"") -> 0 | E31: =VLOOKUP(_xlfn.NUMBERVALUE(F31),Sheet2!$A$1:$B$29,2,FALSE) -> Biak Numfor | F31: 9409 | G31: =IFERROR(IF(VLOOKUP($F31,$F$4:$AP$27,G$27,FALSE)="","",VLOOKUP($F31,$F$4:$AP$27,G$27,FALSE)),"") -> 28 | H31: =IFERROR(IF(VLOOKUP($F31,$F$4:$AP$27,H$27,FALSE)="","",VLOOKUP($F31,$F$4:$AP$27,H$27,FALSE)),"") -> 0 | I31: =IF(IFERROR(IF(VLOOKUP($F31,$F$4:$AP$27,I$27,FALSE)="","",VLOOKUP($F31,$F$4:$AP$27,I$27,FALSE)),"")>G31,G31,IFERROR(IF(VLOOKUP($F31,$F$4:$AP$27,I$27,FALSE)="","",VLOOKUP($F31,$F$4:$AP$27,I$27,FALSE)),"")) -> 28 | J31: =IFERROR(IF(VLOOKUP($F31,$F$4:$AP$27,J$27,FALSE)="","",VLOOKUP($F31,$F$4:$AP$27,J$27,FALSE)),"") -> 1.18 | K31: =IFERROR(IF(VLOOKUP($F31,$F$4:$AP$27,K$27,FALSE)="","",VLOOKUP($F31,$F$4:$AP$27,K$27,FALSE)),"") -> 5 | L31: =IFERROR(IF(VLOOKUP($F31,$F$4:$AP$27,L$27,FALSE)="","",VLOOKUP($F31,$F$4:$AP$27,L$27,FALSE)),"") -> 0 | M31: =IF(IFERROR(IF(VLOOKUP($F31,$F$4:$AP$27,M$27,FALSE)="","",VLOOKUP($F31,$F$4:$AP$27,M$27,FALSE)),"")>K31,K31,IFERROR(IF(VLOOKUP($F31,$F$4:$AP$27,M$27,FALSE)="","",VLOOKUP($F31,$F$4:$AP$27,M$27,FALSE)),"")) -> 5 | N31: =IFERROR(IF(VLOOKUP($F31,$F$4:$AP$27,N$27,FALSE)="","",VLOOKUP($F31,$F$4:$AP$27,N$27,FALSE)),"") -> 1 | O31: =IFERROR(IF(VLOOKUP($F31,$F$4:$AP$27,O$27,FALSE)="","",VLOOKUP($F31,$F$4:$AP$27,O$27,FALSE)),"") | P31: =IFERROR(IF(VLOOKUP($F31,$F$4:$AP$27,P$27,FALSE)="","",VLOOKUP($F31,$F$4:$AP$27,P$27,FALSE)),"") | Q31: =IFERROR(IF(VLOOKUP($F31,$F$4:$AP$27,Q$27,FALSE)="","",VLOOKUP($F31,$F$4:$AP$27,Q$27,FALSE)),"") | R31: =IFERROR(IF(VLOOKUP($F31,$F$4:$AP$27,R$27,FALSE)="","",VLOOKUP($F31,$F$4:$AP$27,R$27,FALSE)),"") | S31: =IFERROR(IF(VLOOKUP($F31,$F$4:$AP$27,S$27,FALSE)="","",VLOOKUP($F31,$F$4:$AP$27,S$27,FALSE)),"") | T31: =IFERROR(IF(VLOOKUP($F31,$F$4:$AP$27,T$27,FALSE)="","",VLOOKUP($F31,$F$4:$AP$27,T$27,FALSE)),"") | U31: =IFERROR(IF(VLOOKUP($F31,$F$4:$AP$27,U$27,FALSE)="","",VLOOKUP($F31,$F$4:$AP$27,U$27,FALSE)),"") | ... AP31: =IFERROR(IF(VLOOKUP($F31,$F$4:$AP$27,AP$27,FALSE)="","",VLOOKUP($F31,$F$4:$AP$27,AP$27,FALSE)),"")
A32: =IFERROR(G32/$G$25,"") -> 0.053191489 | B32: =IFERROR( IF(SUM(H32:I32)/G32>1,1,SUM(H32:I32)/G32),"") -> 1 | C32: =IFERROR(A32*B32,"") -> 0.053191489 | D32: =IFERROR(A32-C32,"") -> 0 | E32: =VLOOKUP(_xlfn.NUMBERVALUE(F32),Sheet2!$A$1:$B$29,2,FALSE) -> Sarmi | F32: 9419 | G32: =IFERROR(IF(VLOOKUP($F32,$F$4:$AP$27,G$27,FALSE)="","",VLOOKUP($F32,$F$4:$AP$27,G$27,FALSE)),"") -> 50 | H32: =IFERROR(IF(VLOOKUP($F32,$F$4:$AP$27,H$27,FALSE)="","",VLOOKUP($F32,$F$4:$AP$27,H$27,FALSE)),"") -> 0 | I32: =IF(IFERROR(IF(VLOOKUP($F32,$F$4:$AP$27,I$27,FALSE)="","",VLOOKUP($F32,$F$4:$AP$27,I$27,FALSE)),"")>G32,G32,IFERROR(IF(VLOOKUP($F32,$F$4:$AP$27,I$27,FALSE)="","",VLOOKUP($F32,$F$4:$AP$27,I$27,FALSE)),"")) -> 50 | J32: =IFERROR(IF(VLOOKUP($F32,$F$4:$AP$27,J$27,FALSE)="","",VLOOKUP($F32,$F$4:$AP$27,J$27,FALSE)),"") -> 1 | K32: =IFERROR(IF(VLOOKUP($F32,$F$4:$AP$27,K$27,FALSE)="","",VLOOKUP($F32,$F$4:$AP$27,K$27,FALSE)),"") | L32: =IFERROR(IF(VLOOKUP($F32,$F$4:$AP$27,L$27,FALSE)="","",VLOOKUP($F32,$F$4:$AP$27,L$27,FALSE)),"") | M32: =IF(IFERROR(IF(VLOOKUP($F32,$F$4:$AP$27,M$27,FALSE)="","",VLOOKUP($F32,$F$4:$AP$27,M$27,FALSE)),"")>K32,K32,IFERROR(IF(VLOOKUP($F32,$F$4:$AP$27,M$27,FALSE)="","",VLOOKUP($F32,$F$4:$AP$27,M$27,FALSE)),"")) | N32: =IFERROR(IF(VLOOKUP($F32,$F$4:$AP$27,N$27,FALSE)="","",VLOOKUP($F32,$F$4:$AP$27,N$27,FALSE)),"") | O32: =IFERROR(IF(VLOOKUP($F32,$F$4:$AP$27,O$27,FALSE)="","",VLOOKUP($F32,$F$4:$AP$27,O$27,FALSE)),"") | P32: =IFERROR(IF(VLOOKUP($F32,$F$4:$AP$27,P$27,FALSE)="","",VLOOKUP($F32,$F$4:$AP$27,P$27,FALSE)),"") | Q32: =IFERROR(IF(VLOOKUP($F32,$F$4:$AP$27,Q$27,FALSE)="","",VLOOKUP($F32,$F$4:$AP$27,Q$27,FALSE)),"") | R32: =IFERROR(IF(VLOOKUP($F32,$F$4:$AP$27,R$27,FALSE)="","",VLOOKUP($F32,$F$4:$AP$27,R$27,FALSE)),"") | S32: =IFERROR(IF(VLOOKUP($F32,$F$4:$AP$27,S$27,FALSE)="","",VLOOKUP($F32,$F$4:$AP$27,S$27,FALSE)),"") | T32: =IFERROR(IF(VLOOKUP($F32,$F$4:$AP$27,T$27,FALSE)="","",VLOOKUP($F32,$F$4:$AP$27,T$27,FALSE)),"") | U32: =IFERROR(IF(VLOOKUP($F32,$F$4:$AP$27,U$27,FALSE)="","",VLOOKUP($F32,$F$4:$AP$27,U$27,FALSE)),"") | ... AP32: =IFERROR(IF(VLOOKUP($F32,$F$4:$AP$27,AP$27,FALSE)="","",VLOOKUP($F32,$F$4:$AP$27,AP$27,FALSE)),"")
A33: =IFERROR(G33/$G$25,"") -> 0.035106383 | B33: =IFERROR( IF(SUM(H33:I33)/G33>1,1,SUM(H33:I33)/G33),"") -> 1 | C33: =IFERROR(A33*B33,"") -> 0.035106383 | D33: =IFERROR(A33-C33,"") -> 0 | E33: =VLOOKUP(_xlfn.NUMBERVALUE(F33),Sheet2!$A$1:$B$29,2,FALSE) -> Keerom | F33: 9420 | G33: =IFERROR(IF(VLOOKUP($F33,$F$4:$AP$27,G$27,FALSE)="","",VLOOKUP($F33,$F$4:$AP$27,G$27,FALSE)),"") -> 33 | H33: =IFERROR(IF(VLOOKUP($F33,$F$4:$AP$27,H$27,FALSE)="","",VLOOKUP($F33,$F$4:$AP$27,H$27,FALSE)),"") -> 0 | I33: =IF(IFERROR(IF(VLOOKUP($F33,$F$4:$AP$27,I$27,FALSE)="","",VLOOKUP($F33,$F$4:$AP$27,I$27,FALSE)),"")>G33,G33,IFERROR(IF(VLOOKUP($F33,$F$4:$AP$27,I$27,FALSE)="","",VLOOKUP($F33,$F$4:$AP$27,I$27,FALSE)),"")) -> 33 | J33: =IFERROR(IF(VLOOKUP($F33,$F$4:$AP$27,J$27,FALSE)="","",VLOOKUP($F33,$F$4:$AP$27,J$27,FALSE)),"") -> 1 | K33: =IFERROR(IF(VLOOKUP($F33,$F$4:$AP$27,K$27,FALSE)="","",VLOOKUP($F33,$F$4:$AP$27,K$27,FALSE)),"") | L33: =IFERROR(IF(VLOOKUP($F33,$F$4:$AP$27,L$27,FALSE)="","",VLOOKUP($F33,$F$4:$AP$27,L$27,FALSE)),"") | M33: =IF(IFERROR(IF(VLOOKUP($F33,$F$4:$AP$27,M$27,FALSE)="","",VLOOKUP($F33,$F$4:$AP$27,M$27,FALSE)),"")>K33,K33,IFERROR(IF(VLOOKUP($F33,$F$4:$AP$27,M$27,FALSE)="","",VLOOKUP($F33,$F$4:$AP$27,M$27,FALSE)),"")) | N33: =IFERROR(IF(VLOOKUP($F33,$F$4:$AP$27,N$27,FALSE)="","",VLOOKUP($F33,$F$4:$AP$27,N$27,FALSE)),"") | O33: =IFERROR(IF(VLOOKUP($F33,$F$4:$AP$27,O$27,FALSE)="","",VLOOKUP($F33,$F$4:$AP$27,O$27,FALSE)),"") | P33: =IFERROR(IF(VLOOKUP($F33,$F$4:$AP$27,P$27,FALSE)="","",VLOOKUP($F33,$F$4:$AP$27,P$27,FALSE)),"") | Q33: =IFERROR(IF(VLOOKUP($F33,$F$4:$AP$27,Q$27,FALSE)="","",VLOOKUP($F33,$F$4:$AP$27,Q$27,FALSE)),"") | R33: =IFERROR(IF(VLOOKUP($F33,$F$4:$AP$27,R$27,FALSE)="","",VLOOKUP($F33,$F$4:$AP$27,R$27,FALSE)),"") | S33: =IFERROR(IF(VLOOKUP($F33,$F$4:$AP$27,S$27,FALSE)="","",VLOOKUP($F33,$F$4:$AP$27,S$27,FALSE)),"") | T33: =IFERROR(IF(VLOOKUP($F33,$F$4:$AP$27,T$27,FALSE)="","",VLOOKUP($F33,$F$4:$AP$27,T$27,FALSE)),"") | U33: =IFERROR(IF(VLOOKUP($F33,$F$4:$AP$27,U$27,FALSE)="","",VLOOKUP($F33,$F$4:$AP$27,U$27,FALSE)),"") | ... AP33: =IFERROR(IF(VLOOKUP($F33,$F$4:$AP$27,AP$27,FALSE)="","",VLOOKUP($F33,$F$4:$AP$27,AP$27,FALSE)),"")
A34: =IFERROR(G34/$G$25,"") -> 0.010638298 | B34: =IFERROR( IF(SUM(H34:I34)/G34>1,1,SUM(H34:I34)/G34),"") -> 1 | C34: =IFERROR(A34*B34,"") -> 0.010638298 | D34: =IFERROR(A34-C34,"") -> 0 | E34: =VLOOKUP(_xlfn.NUMBERVALUE(F34),Sheet2!$A$1:$B$29,2,FALSE) -> Waropen | F34: 9426 | G34: =IFERROR(IF(VLOOKUP($F34,$F$4:$AP$27,G$27,FALSE)="","",VLOOKUP($F34,$F$4:$AP$27,G$27,FALSE)),"") -> 10 | H34: =IFERROR(IF(VLOOKUP($F34,$F$4:$AP$27,H$27,FALSE)="","",VLOOKUP($F34,$F$4:$AP$27,H$27,FALSE)),"") -> 0 | I34: =IF(IFERROR(IF(VLOOKUP($F34,$F$4:$AP$27,I$27,FALSE)="","",VLOOKUP($F34,$F$4:$AP$27,I$27,FALSE)),"")>G34,G34,IFERROR(IF(VLOOKUP($F34,$F$4:$AP$27,I$27,FALSE)="","",VLOOKUP($F34,$F$4:$AP$27,I$27,FALSE)),"")) -> 10 | J34: =IFERROR(IF(VLOOKUP($F34,$F$4:$AP$27,J$27,FALSE)="","",VLOOKUP($F34,$F$4:$AP$27,J$27,FALSE)),"") -> 1 | K34: =IFERROR(IF(VLOOKUP($F34,$F$4:$AP$27,K$27,FALSE)="","",VLOOKUP($F34,$F$4:$AP$27,K$27,FALSE)),"") | L34: =IFERROR(IF(VLOOKUP($F34,$F$4:$AP$27,L$27,FALSE)="","",VLOOKUP($F34,$F$4:$AP$27,L$27,FALSE)),"") | M34: =IF(IFERROR(IF(VLOOKUP($F34,$F$4:$AP$27,M$27,FALSE)="","",VLOOKUP($F34,$F$4:$AP$27,M$27,FALSE)),"")>K34,K34,IFERROR(IF(VLOOKUP($F34,$F$4:$AP$27,M$27,FALSE)="","",VLOOKUP($F34,$F$4:$AP$27,M$27,FALSE)),"")) | N34: =IFERROR(IF(VLOOKUP($F34,$F$4:$AP$27,N$27,FALSE)="","",VLOOKUP($F34,$F$4:$AP$27,N$27,FALSE)),"") | O34: =IFERROR(IF(VLOOKUP($F34,$F$4:$AP$27,O$27,FALSE)="","",VLOOKUP($F34,$F$4:$AP$27,O$27,FALSE)),"") | P34: =IFERROR(IF(VLOOKUP($F34,$F$4:$AP$27,P$27,FALSE)="","",VLOOKUP($F34,$F$4:$AP$27,P$27,FALSE)),"") | Q34: =IFERROR(IF(VLOOKUP($F34,$F$4:$AP$27,Q$27,FALSE)="","",VLOOKUP($F34,$F$4:$AP$27,Q$27,FALSE)),"") | R34: =IFERROR(IF(VLOOKUP($F34,$F$4:$AP$27,R$27,FALSE)="","",VLOOKUP($F34,$F$4:$AP$27,R$27,FALSE)),"") | S34: =IFERROR(IF(VLOOKUP($F34,$F$4:$AP$27,S$27,FALSE)="","",VLOOKUP($F34,$F$4:$AP$27,S$27,FALSE)),"") | T34: =IFERROR(IF(VLOOKUP($F34,$F$4:$AP$27,T$27,FALSE)="","",VLOOKUP($F34,$F$4:$AP$27,T$27,FALSE)),"") | U34: =IFERROR(IF(VLOOKUP($F34,$F$4:$AP$27,U$27,FALSE)="","",VLOOKUP($F34,$F$4:$AP$27,U$27,FALSE)),"") | ... AP34: =IFERROR(IF(VLOOKUP($F34,$F$4:$AP$27,AP$27,FALSE)="","",VLOOKUP($F34,$F$4:$AP$27,AP$27,FALSE)),"")
A35: =IFERROR(G35/$G$25,"") -> 0.030851064 | B35: =IFERROR( IF(SUM(H35:I35)/G35>1,1,SUM(H35:I35)/G35),"") -> 1 | C35: =IFERROR(A35*B35,"") -> 0.030851064 | D35: =IFERROR(A35-C35,"") -> 0 | E35: =VLOOKUP(_xlfn.NUMBERVALUE(F35),Sheet2!$A$1:$B$29,2,FALSE) -> Supiori | F35: 9427 | G35: =IFERROR(IF(VLOOKUP($F35,$F$4:$AP$27,G$27,FALSE)="","",VLOOKUP($F35,$F$4:$AP$27,G$27,FALSE)),"") -> 29 | H35: =IFERROR(IF(VLOOKUP($F35,$F$4:$AP$27,H$27,FALSE)="","",VLOOKUP($F35,$F$4:$AP$27,H$27,FALSE)),"") -> 0 | I35: =IF(IFERROR(IF(VLOOKUP($F35,$F$4:$AP$27,I$27,FALSE)="","",VLOOKUP($F35,$F$4:$AP$27,I$27,FALSE)),"")>G35,G35,IFERROR(IF(VLOOKUP($F35,$F$4:$AP$27,I$27,FALSE)="","",VLOOKUP($F35,$F$4:$AP$27,I$27,FALSE)),"")) -> 29 | J35: =IFERROR(IF(VLOOKUP($F35,$F$4:$AP$27,J$27,FALSE)="","",VLOOKUP($F35,$F$4:$AP$27,J$27,FALSE)),"") -> 1 | K35: =IFERROR(IF(VLOOKUP($F35,$F$4:$AP$27,K$27,FALSE)="","",VLOOKUP($F35,$F$4:$AP$27,K$27,FALSE)),"") | L35: =IFERROR(IF(VLOOKUP($F35,$F$4:$AP$27,L$27,FALSE)="","",VLOOKUP($F35,$F$4:$AP$27,L$27,FALSE)),"") | M35: =IF(IFERROR(IF(VLOOKUP($F35,$F$4:$AP$27,M$27,FALSE)="","",VLOOKUP($F35,$F$4:$AP$27,M$27,FALSE)),"")>K35,K35,IFERROR(IF(VLOOKUP($F35,$F$4:$AP$27,M$27,FALSE)="","",VLOOKUP($F35,$F$4:$AP$27,M$27,FALSE)),"")) | N35: =IFERROR(IF(VLOOKUP($F35,$F$4:$AP$27,N$27,FALSE)="","",VLOOKUP($F35,$F$4:$AP$27,N$27,FALSE)),"") | O35: =IFERROR(IF(VLOOKUP($F35,$F$4:$AP$27,O$27,FALSE)="","",VLOOKUP($F35,$F$4:$AP$27,O$27,FALSE)),"") | P35: =IFERROR(IF(VLOOKUP($F35,$F$4:$AP$27,P$27,FALSE)="","",VLOOKUP($F35,$F$4:$AP$27,P$27,FALSE)),"") | Q35: =IFERROR(IF(VLOOKUP($F35,$F$4:$AP$27,Q$27,FALSE)="","",VLOOKUP($F35,$F$4:$AP$27,Q$27,FALSE)),"") | R35: =IFERROR(IF(VLOOKUP($F35,$F$4:$AP$27,R$27,FALSE)="","",VLOOKUP($F35,$F$4:$AP$27,R$27,FALSE)),"") | S35: =IFERROR(IF(VLOOKUP($F35,$F$4:$AP$27,S$27,FALSE)="","",VLOOKUP($F35,$F$4:$AP$27,S$27,FALSE)),"") | T35: =IFERROR(IF(VLOOKUP($F35,$F$4:$AP$27,T$27,FALSE)="","",VLOOKUP($F35,$F$4:$AP$27,T$27,FALSE)),"") | U35: =IFERROR(IF(VLOOKUP($F35,$F$4:$AP$27,U$27,FALSE)="","",VLOOKUP($F35,$F$4:$AP$27,U$27,FALSE)),"") | ... AP35: =IFERROR(IF(VLOOKUP($F35,$F$4:$AP$27,AP$27,FALSE)="","",VLOOKUP($F35,$F$4:$AP$27,AP$27,FALSE)),"")
A36: =IFERROR(G36/$G$25,"") -> 0.0053191489 | B36: =IFERROR( IF(SUM(H36:I36)/G36>1,1,SUM(H36:I36)/G36),"") -> 1 | C36: =IFERROR(A36*B36,"") -> 0.0053191489 | D36: =IFERROR(A36-C36,"") -> 0 | E36: =VLOOKUP(_xlfn.NUMBERVALUE(F36),Sheet2!$A$1:$B$29,2,FALSE) -> Mamberamo Raya | F36: 9428 | G36: =IFERROR(IF(VLOOKUP($F36,$F$4:$AP$27,G$27,FALSE)="","",VLOOKUP($F36,$F$4:$AP$27,G$27,FALSE)),"") -> 5 | H36: =IFERROR(IF(VLOOKUP($F36,$F$4:$AP$27,H$27,FALSE)="","",VLOOKUP($F36,$F$4:$AP$27,H$27,FALSE)),"") -> 0 | I36: =IF(IFERROR(IF(VLOOKUP($F36,$F$4:$AP$27,I$27,FALSE)="","",VLOOKUP($F36,$F$4:$AP$27,I$27,FALSE)),"")>G36,G36,IFERROR(IF(VLOOKUP($F36,$F$4:$AP$27,I$27,FALSE)="","",VLOOKUP($F36,$F$4:$AP$27,I$27,FALSE)),"")) -> 5 | J36: =IFERROR(IF(VLOOKUP($F36,$F$4:$AP$27,J$27,FALSE)="","",VLOOKUP($F36,$F$4:$AP$27,J$27,FALSE)),"") -> 1 | K36: =IFERROR(IF(VLOOKUP($F36,$F$4:$AP$27,K$27,FALSE)="","",VLOOKUP($F36,$F$4:$AP$27,K$27,FALSE)),"") | L36: =IFERROR(IF(VLOOKUP($F36,$F$4:$AP$27,L$27,FALSE)="","",VLOOKUP($F36,$F$4:$AP$27,L$27,FALSE)),"") | M36: =IF(IFERROR(IF(VLOOKUP($F36,$F$4:$AP$27,M$27,FALSE)="","",VLOOKUP($F36,$F$4:$AP$27,M$27,FALSE)),"")>K36,K36,IFERROR(IF(VLOOKUP($F36,$F$4:$AP$27,M$27,FALSE)="","",VLOOKUP($F36,$F$4:$AP$27,M$27,FALSE)),"")) | N36: =IFERROR(IF(VLOOKUP($F36,$F$4:$AP$27,N$27,FALSE)="","",VLOOKUP($F36,$F$4:$AP$27,N$27,FALSE)),"") | O36: =IFERROR(IF(VLOOKUP($F36,$F$4:$AP$27,O$27,FALSE)="","",VLOOKUP($F36,$F$4:$AP$27,O$27,FALSE)),"") | P36: =IFERROR(IF(VLOOKUP($F36,$F$4:$AP$27,P$27,FALSE)="","",VLOOKUP($F36,$F$4:$AP$27,P$27,FALSE)),"") | Q36: =IFERROR(IF(VLOOKUP($F36,$F$4:$AP$27,Q$27,FALSE)="","",VLOOKUP($F36,$F$4:$AP$27,Q$27,FALSE)),"") | R36: =IFERROR(IF(VLOOKUP($F36,$F$4:$AP$27,R$27,FALSE)="","",VLOOKUP($F36,$F$4:$AP$27,R$27,FALSE)),"") | S36: =IFERROR(IF(VLOOKUP($F36,$F$4:$AP$27,S$27,FALSE)="","",VLOOKUP($F36,$F$4:$AP$27,S$27,FALSE)),"") | T36: =IFERROR(IF(VLOOKUP($F36,$F$4:$AP$27,T$27,FALSE)="","",VLOOKUP($F36,$F$4:$AP$27,T$27,FALSE)),"") | U36: =IFERROR(IF(VLOOKUP($F36,$F$4:$AP$27,U$27,FALSE)="","",VLOOKUP($F36,$F$4:$AP$27,U$27,FALSE)),"") | ... AP36: =IFERROR(IF(VLOOKUP($F36,$F$4:$AP$27,AP$27,FALSE)="","",VLOOKUP($F36,$F$4:$AP$27,AP$27,FALSE)),"")
A37: =IFERROR(G37/$G$25,"") -> 0.10106383 | B37: =IFERROR( IF(SUM(H37:I37)/G37>1,1,SUM(H37:I37)/G37),"") -> 1 | C37: =IFERROR(A37*B37,"") -> 0.10106383 | D37: =IFERROR(A37-C37,"") -> 0 | E37: =VLOOKUP(_xlfn.NUMBERVALUE(F37),Sheet2!$A$1:$B$29,2,FALSE) -> Kota Jayapura | F37: 9471 | G37: =IFERROR(IF(VLOOKUP($F37,$F$4:$AP$27,G$27,FALSE)="","",VLOOKUP($F37,$F$4:$AP$27,G$27,FALSE)),"") -> 95 | H37: =IFERROR(IF(VLOOKUP($F37,$F$4:$AP$27,H$27,FALSE)="","",VLOOKUP($F37,$F$4:$AP$27,H$27,FALSE)),"") -> 0 | I37: =IF(IFERROR(IF(VLOOKUP($F37,$F$4:$AP$27,I$27,FALSE)="","",VLOOKUP($F37,$F$4:$AP$27,I$27,FALSE)),"")>G37,G37,IFERROR(IF(VLOOKUP($F37,$F$4:$AP$27,I$27,FALSE)="","",VLOOKUP($F37,$F$4:$AP$27,I$27,FALSE)),"")) -> 95 | J37: =IFERROR(IF(VLOOKUP($F37,$F$4:$AP$27,J$27,FALSE)="","",VLOOKUP($F37,$F$4:$AP$27,J$27,FALSE)),"") -> 1.01 | K37: =IFERROR(IF(VLOOKUP($F37,$F$4:$AP$27,K$27,FALSE)="","",VLOOKUP($F37,$F$4:$AP$27,K$27,FALSE)),"") -> 44 | L37: =IFERROR(IF(VLOOKUP($F37,$F$4:$AP$27,L$27,FALSE)="","",VLOOKUP($F37,$F$4:$AP$27,L$27,FALSE)),"") -> 0 | M37: =IF(IFERROR(IF(VLOOKUP($F37,$F$4:$AP$27,M$27,FALSE)="","",VLOOKUP($F37,$F$4:$AP$27,M$27,FALSE)),"")>K37,K37,IFERROR(IF(VLOOKUP($F37,$F$4:$AP$27,M$27,FALSE)="","",VLOOKUP($F37,$F$4:$AP$27,M$27,FALSE)),"")) -> 44 | N37: =IFERROR(IF(VLOOKUP($F37,$F$4:$AP$27,N$27,FALSE)="","",VLOOKUP($F37,$F$4:$AP$27,N$27,FALSE)),"") -> 1 | O37: =IFERROR(IF(VLOOKUP($F37,$F$4:$AP$27,O$27,FALSE)="","",VLOOKUP($F37,$F$4:$AP$27,O$27,FALSE)),"") | P37: =IFERROR(IF(VLOOKUP($F37,$F$4:$AP$27,P$27,FALSE)="","",VLOOKUP($F37,$F$4:$AP$27,P$27,FALSE)),"") | Q37: =IFERROR(IF(VLOOKUP($F37,$F$4:$AP$27,Q$27,FALSE)="","",VLOOKUP($F37,$F$4:$AP$27,Q$27,FALSE)),"") | R37: =IFERROR(IF(VLOOKUP($F37,$F$4:$AP$27,R$27,FALSE)="","",VLOOKUP($F37,$F$4:$AP$27,R$27,FALSE)),"") | S37: =IFERROR(IF(VLOOKUP($F37,$F$4:$AP$27,S$27,FALSE)="","",VLOOKUP($F37,$F$4:$AP$27,S$27,FALSE)),"") | T37: =IFERROR(IF(VLOOKUP($F37,$F$4:$AP$27,T$27,FALSE)="","",VLOOKUP($F37,$F$4:$AP$27,T$27,FALSE)),"") | U37: =IFERROR(IF(VLOOKUP($F37,$F$4:$AP$27,U$27,FALSE)="","",VLOOKUP($F37,$F$4:$AP$27,U$27,FALSE)),"") | ... AP37: =IFERROR(IF(VLOOKUP($F37,$F$4:$AP$27,AP$27,FALSE)="","",VLOOKUP($F37,$F$4:$AP$27,AP$27,FALSE)),"")
A38: =IFERROR(G38/$G$25,"") | B38: =IFERROR( IF(SUM(H38:I38)/G38>1,1,SUM(H38:I38)/G38),"") | C38: =IFERROR(A38*B38,"") | D38: =IFERROR(A38-C38,"") | F38: 9500 | G38: =IFERROR(IF(VLOOKUP($F38,$F$4:$AP$27,G$27,FALSE)="","",VLOOKUP($F38,$F$4:$AP$27,G$27,FALSE)),"") | H38: =IFERROR(IF(VLOOKUP($F38,$F$4:$AP$27,H$27,FALSE)="","",VLOOKUP($F38,$F$4:$AP$27,H$27,FALSE)),"") | I38: =IF(IFERROR(IF(VLOOKUP($F38,$F$4:$AP$27,I$27,FALSE)="","",VLOOKUP($F38,$F$4:$AP$27,I$27,FALSE)),"")>G38,G38,IFERROR(IF(VLOOKUP($F38,$F$4:$AP$27,I$27,FALSE)="","",VLOOKUP($F38,$F$4:$AP$27,I$27,FALSE)),"")) | J38: =IFERROR(IF(VLOOKUP($F38,$F$4:$AP$27,J$27,FALSE)="","",VLOOKUP($F38,$F$4:$AP$27,J$27,FALSE)),"") | K38: =IFERROR(IF(VLOOKUP($F38,$F$4:$AP$27,K$27,FALSE)="","",VLOOKUP($F38,$F$4:$AP$27,K$27,FALSE)),"") | L38: =IFERROR(IF(VLOOKUP($F38,$F$4:$AP$27,L$27,FALSE)="","",VLOOKUP($F38,$F$4:$AP$27,L$27,FALSE)),"") | M38: =IF(IFERROR(IF(VLOOKUP($F38,$F$4:$AP$27,M$27,FALSE)="","",VLOOKUP($F38,$F$4:$AP$27,M$27,FALSE)),"")>K38,K38,IFERROR(IF(VLOOKUP($F38,$F$4:$AP$27,M$27,FALSE)="","",VLOOKUP($F38,$F$4:$AP$27,M$27,FALSE)),"")) | N38: =IFERROR(IF(VLOOKUP($F38,$F$4:$AP$27,N$27,FALSE)="","",VLOOKUP($F38,$F$4:$AP$27,N$27,FALSE)),"") | O38: =IFERROR(IF(VLOOKUP($F38,$F$4:$AP$27,O$27,FALSE)="","",VLOOKUP($F38,$F$4:$AP$27,O$27,FALSE)),"") | P38: =IFERROR(IF(VLOOKUP($F38,$F$4:$AP$27,P$27,FALSE)="","",VLOOKUP($F38,$F$4:$AP$27,P$27,FALSE)),"") | Q38: =IFERROR(IF(VLOOKUP($F38,$F$4:$AP$27,Q$27,FALSE)="","",VLOOKUP($F38,$F$4:$AP$27,Q$27,FALSE)),"") | S38: =IFERROR(IF(VLOOKUP($F38,$F$4:$AP$27,S$27,FALSE)="","",VLOOKUP($F38,$F$4:$AP$27,S$27,FALSE)),"") | T38: =IFERROR(IF(VLOOKUP($F38,$F$4:$AP$27,T$27,FALSE)="","",VLOOKUP($F38,$F$4:$AP$27,T$27,FALSE)),"") | U38: =IFERROR(IF(VLOOKUP($F38,$F$4:$AP$27,U$27,FALSE)="","",VLOOKUP($F38,$F$4:$AP$27,U$27,FALSE)),"") | V38: =IFERROR(IF(VLOOKUP($F38,$F$4:$AP$27,V$27,FALSE)="","",VLOOKUP($F38,$F$4:$AP$27,V$27,FALSE)),"") | W38: =IFERROR(IF(VLOOKUP($F38,$F$4:$AP$27,W$27,FALSE)="","",VLOOKUP($F38,$F$4:$AP$27,W$27,FALSE)),"") | X38: =IFERROR(IF(VLOOKUP($F38,$F$4:$AP$27,X$27,FALSE)="","",VLOOKUP($F38,$F$4:$AP$27,X$27,FALSE)),"") | Y38: =IFERROR(IF(VLOOKUP($F38,$F$4:$AP$27,Y$27,FALSE)="","",VLOOKUP($F38,$F$4:$AP$27,Y$27,FALSE)),"") | Z38: =IFERROR(IF(VLOOKUP($F38,$F$4:$AP$27,Z$27,FALSE)="","",VLOOKUP($F38,$F$4:$AP$27,Z$27,FALSE)),"") | ... AP38: =IFERROR(IF(VLOOKUP($F38,$F$4:$AP$27,AP$27,FALSE)="","",VLOOKUP($F38,$F$4:$AP$27,AP$27,FALSE)),"")
A39: =IFERROR(G39/$G$25,"") -> 0.21595745 | B39: =IFERROR( IF(SUM(H39:I39)/G39>1,1,SUM(H39:I39)/G39),"") -> 0.99507389 | C39: =IFERROR(A39*B39,"") -> 0.21489362 | D39: =IFERROR(A39-C39,"") -> 0.0010638298 | E39: =VLOOKUP(_xlfn.NUMBERVALUE(F39),Sheet2!$A$1:$B$29,2,FALSE) -> Merauke | F39: 9501 | G39: =IFERROR(IF(VLOOKUP($F39,$F$4:$AP$27,G$27,FALSE)="","",VLOOKUP($F39,$F$4:$AP$27,G$27,FALSE)),"") -> 203 | H39: =IFERROR(IF(VLOOKUP($F39,$F$4:$AP$27,H$27,FALSE)="","",VLOOKUP($F39,$F$4:$AP$27,H$27,FALSE)),"") -> 0 | I39: =IF(IFERROR(IF(VLOOKUP($F39,$F$4:$AP$27,I$27,FALSE)="","",VLOOKUP($F39,$F$4:$AP$27,I$27,FALSE)),"")>G39,G39,IFERROR(IF(VLOOKUP($F39,$F$4:$AP$27,I$27,FALSE)="","",VLOOKUP($F39,$F$4:$AP$27,I$27,FALSE)),"")) -> 202 | J39: =IFERROR(IF(VLOOKUP($F39,$F$4:$AP$27,J$27,FALSE)="","",VLOOKUP($F39,$F$4:$AP$27,J$27,FALSE)),"") -> 1 | K39: =IFERROR(IF(VLOOKUP($F39,$F$4:$AP$27,K$27,FALSE)="","",VLOOKUP($F39,$F$4:$AP$27,K$27,FALSE)),"") -> 14 | L39: =IFERROR(IF(VLOOKUP($F39,$F$4:$AP$27,L$27,FALSE)="","",VLOOKUP($F39,$F$4:$AP$27,L$27,FALSE)),"") -> 0 | M39: =IF(IFERROR(IF(VLOOKUP($F39,$F$4:$AP$27,M$27,FALSE)="","",VLOOKUP($F39,$F$4:$AP$27,M$27,FALSE)),"")>K39,K39,IFERROR(IF(VLOOKUP($F39,$F$4:$AP$27,M$27,FALSE)="","",VLOOKUP($F39,$F$4:$AP$27,M$27,FALSE)),"")) -> 14 | N39: =IFERROR(IF(VLOOKUP($F39,$F$4:$AP$27,N$27,FALSE)="","",VLOOKUP($F39,$F$4:$AP$27,N$27,FALSE)),"") -> 1 | O39: =IFERROR(IF(VLOOKUP($F39,$F$4:$AP$27,O$27,FALSE)="","",VLOOKUP($F39,$F$4:$AP$27,O$27,FALSE)),"") | P39: =IFERROR(IF(VLOOKUP($F39,$F$4:$AP$27,P$27,FALSE)="","",VLOOKUP($F39,$F$4:$AP$27,P$27,FALSE)),"") | Q39: =IFERROR(IF(VLOOKUP($F39,$F$4:$AP$27,Q$27,FALSE)="","",VLOOKUP($F39,$F$4:$AP$27,Q$27,FALSE)),"") | R39: =IFERROR(IF(VLOOKUP($F39,$F$4:$AP$27,R$27,FALSE)="","",VLOOKUP($F39,$F$4:$AP$27,R$27,FALSE)),"") | S39: =IFERROR(IF(VLOOKUP($F39,$F$4:$AP$27,S$27,FALSE)="","",VLOOKUP($F39,$F$4:$AP$27,S$27,FALSE)),"") | T39: =IFERROR(IF(VLOOKUP($F39,$F$4:$AP$27,T$27,FALSE)="","",VLOOKUP($F39,$F$4:$AP$27,T$27,FALSE)),"") | U39: =IFERROR(IF(VLOOKUP($F39,$F$4:$AP$27,U$27,FALSE)="","",VLOOKUP($F39,$F$4:$AP$27,U$27,FALSE)),"") | ... AP39: =IFERROR(IF(VLOOKUP($F39,$F$4:$AP$27,AP$27,FALSE)="","",VLOOKUP($F39,$F$4:$AP$27,AP$27,FALSE)),"")
A40: =IFERROR(G40/$G$25,"") -> 0.061702128 | B40: =IFERROR( IF(SUM(H40:I40)/G40>1,1,SUM(H40:I40)/G40),"") -> 1 | C40: =IFERROR(A40*B40,"") -> 0.061702128 | D40: =IFERROR(A40-C40,"") -> 0 | E40: =VLOOKUP(_xlfn.NUMBERVALUE(F40),Sheet2!$A$1:$B$29,2,FALSE) -> Boven Digoel | F40: 9502 | G40: =IFERROR(IF(VLOOKUP($F40,$F$4:$AP$27,G$27,FALSE)="","",VLOOKUP($F40,$F$4:$AP$27,G$27,FALSE)),"") -> 58 | H40: =IFERROR(IF(VLOOKUP($F40,$F$4:$AP$27,H$27,FALSE)="","",VLOOKUP($F40,$F$4:$AP$27,H$27,FALSE)),"") -> 0 | I40: =IF(IFERROR(IF(VLOOKUP($F40,$F$4:$AP$27,I$27,FALSE)="","",VLOOKUP($F40,$F$4:$AP$27,I$27,FALSE)),"")>G40,G40,IFERROR(IF(VLOOKUP($F40,$F$4:$AP$27,I$27,FALSE)="","",VLOOKUP($F40,$F$4:$AP$27,I$27,FALSE)),"")) -> 58 | J40: =IFERROR(IF(VLOOKUP($F40,$F$4:$AP$27,J$27,FALSE)="","",VLOOKUP($F40,$F$4:$AP$27,J$27,FALSE)),"") -> 1 | K40: =IFERROR(IF(VLOOKUP($F40,$F$4:$AP$27,K$27,FALSE)="","",VLOOKUP($F40,$F$4:$AP$27,K$27,FALSE)),"") -> 4 | L40: =IFERROR(IF(VLOOKUP($F40,$F$4:$AP$27,L$27,FALSE)="","",VLOOKUP($F40,$F$4:$AP$27,L$27,FALSE)),"") -> 0 | M40: =IF(IFERROR(IF(VLOOKUP($F40,$F$4:$AP$27,M$27,FALSE)="","",VLOOKUP($F40,$F$4:$AP$27,M$27,FALSE)),"")>K40,K40,IFERROR(IF(VLOOKUP($F40,$F$4:$AP$27,M$27,FALSE)="","",VLOOKUP($F40,$F$4:$AP$27,M$27,FALSE)),"")) -> 2 | N40: =IFERROR(IF(VLOOKUP($F40,$F$4:$AP$27,N$27,FALSE)="","",VLOOKUP($F40,$F$4:$AP$27,N$27,FALSE)),"") -> 0.5 | O40: =IFERROR(IF(VLOOKUP($F40,$F$4:$AP$27,O$27,FALSE)="","",VLOOKUP($F40,$F$4:$AP$27,O$27,FALSE)),"") | P40: =IFERROR(IF(VLOOKUP($F40,$F$4:$AP$27,P$27,FALSE)="","",VLOOKUP($F40,$F$4:$AP$27,P$27,FALSE)),"") | Q40: =IFERROR(IF(VLOOKUP($F40,$F$4:$AP$27,Q$27,FALSE)="","",VLOOKUP($F40,$F$4:$AP$27,Q$27,FALSE)),"") | R40: =IFERROR(IF(VLOOKUP($F40,$F$4:$AP$27,R$27,FALSE)="","",VLOOKUP($F40,$F$4:$AP$27,R$27,FALSE)),"") | S40: =IFERROR(IF(VLOOKUP($F40,$F$4:$AP$27,S$27,FALSE)="","",VLOOKUP($F40,$F$4:$AP$27,S$27,FALSE)),"") | T40: =IFERROR(IF(VLOOKUP($F40,$F$4:$AP$27,T$27,FALSE)="","",VLOOKUP($F40,$F$4:$AP$27,T$27,FALSE)),"") | U40: =IFERROR(IF(VLOOKUP($F40,$F$4:$AP$27,U$27,FALSE)="","",VLOOKUP($F40,$F$4:$AP$27,U$27,FALSE)),"") | ... AP40: =IFERROR(IF(VLOOKUP($F40,$F$4:$AP$27,AP$27,FALSE)="","",VLOOKUP($F40,$F$4:$AP$27,AP$27,FALSE)),"")
A41: =IFERROR(G41/$G$25,"") -> 0.039361702 | B41: =IFERROR( IF(SUM(H41:I41)/G41>1,1,SUM(H41:I41)/G41),"") -> 1 | C41: =IFERROR(A41*B41,"") -> 0.039361702 | D41: =IFERROR(A41-C41,"") -> 0 | E41: =VLOOKUP(_xlfn.NUMBERVALUE(F41),Sheet2!$A$1:$B$29,2,FALSE) -> Mappi | F41: 9503 | G41: =IFERROR(IF(VLOOKUP($F41,$F$4:$AP$27,G$27,FALSE)="","",VLOOKUP($F41,$F$4:$AP$27,G$27,FALSE)),"") -> 37 | H41: =IFERROR(IF(VLOOKUP($F41,$F$4:$AP$27,H$27,FALSE)="","",VLOOKUP($F41,$F$4:$AP$27,H$27,FALSE)),"") -> 0 | I41: =IF(IFERROR(IF(VLOOKUP($F41,$F$4:$AP$27,I$27,FALSE)="","",VLOOKUP($F41,$F$4:$AP$27,I$27,FALSE)),"")>G41,G41,IFERROR(IF(VLOOKUP($F41,$F$4:$AP$27,I$27,FALSE)="","",VLOOKUP($F41,$F$4:$AP$27,I$27,FALSE)),"")) -> 37 | J41: =IFERROR(IF(VLOOKUP($F41,$F$4:$AP$27,J$27,FALSE)="","",VLOOKUP($F41,$F$4:$AP$27,J$27,FALSE)),"") -> 1 | K41: =IFERROR(IF(VLOOKUP($F41,$F$4:$AP$27,K$27,FALSE)="","",VLOOKUP($F41,$F$4:$AP$27,K$27,FALSE)),"") -> 6 | L41: =IFERROR(IF(VLOOKUP($F41,$F$4:$AP$27,L$27,FALSE)="","",VLOOKUP($F41,$F$4:$AP$27,L$27,FALSE)),"") -> 0 | M41: =IF(IFERROR(IF(VLOOKUP($F41,$F$4:$AP$27,M$27,FALSE)="","",VLOOKUP($F41,$F$4:$AP$27,M$27,FALSE)),"")>K41,K41,IFERROR(IF(VLOOKUP($F41,$F$4:$AP$27,M$27,FALSE)="","",VLOOKUP($F41,$F$4:$AP$27,M$27,FALSE)),"")) -> 6 | N41: =IFERROR(IF(VLOOKUP($F41,$F$4:$AP$27,N$27,FALSE)="","",VLOOKUP($F41,$F$4:$AP$27,N$27,FALSE)),"") -> 1 | O41: =IFERROR(IF(VLOOKUP($F41,$F$4:$AP$27,O$27,FALSE)="","",VLOOKUP($F41,$F$4:$AP$27,O$27,FALSE)),"") | P41: =IFERROR(IF(VLOOKUP($F41,$F$4:$AP$27,P$27,FALSE)="","",VLOOKUP($F41,$F$4:$AP$27,P$27,FALSE)),"") | Q41: =IFERROR(IF(VLOOKUP($F41,$F$4:$AP$27,Q$27,FALSE)="","",VLOOKUP($F41,$F$4:$AP$27,Q$27,FALSE)),"") | R41: =IFERROR(IF(VLOOKUP($F41,$F$4:$AP$27,R$27,FALSE)="","",VLOOKUP($F41,$F$4:$AP$27,R$27,FALSE)),"") | S41: =IFERROR(IF(VLOOKUP($F41,$F$4:$AP$27,S$27,FALSE)="","",VLOOKUP($F41,$F$4:$AP$27,S$27,FALSE)),"") | T41: =IFERROR(IF(VLOOKUP($F41,$F$4:$AP$27,T$27,FALSE)="","",VLOOKUP($F41,$F$4:$AP$27,T$27,FALSE)),"") | U41: =IFERROR(IF(VLOOKUP($F41,$F$4:$AP$27,U$27,FALSE)="","",VLOOKUP($F41,$F$4:$AP$27,U$27,FALSE)),"") | ... AP41: =IFERROR(IF(VLOOKUP($F41,$F$4:$AP$27,AP$27,FALSE)="","",VLOOKUP($F41,$F$4:$AP$27,AP$27,FALSE)),"")
A42: =IFERROR(G42/$G$25,"") -> 0.042553191 | B42: =IFERROR( IF(SUM(H42:I42)/G42>1,1,SUM(H42:I42)/G42),"") -> 1 | C42: =IFERROR(A42*B42,"") -> 0.042553191 | D42: =IFERROR(A42-C42,"") -> 0 | E42: =VLOOKUP(_xlfn.NUMBERVALUE(F42),Sheet2!$A$1:$B$29,2,FALSE) -> Asmat | F42: 9504 | G42: =IFERROR(IF(VLOOKUP($F42,$F$4:$AP$27,G$27,FALSE)="","",VLOOKUP($F42,$F$4:$AP$27,G$27,FALSE)),"") -> 40 | H42: =IFERROR(IF(VLOOKUP($F42,$F$4:$AP$27,H$27,FALSE)="","",VLOOKUP($F42,$F$4:$AP$27,H$27,FALSE)),"") -> 0 | I42: =IF(IFERROR(IF(VLOOKUP($F42,$F$4:$AP$27,I$27,FALSE)="","",VLOOKUP($F42,$F$4:$AP$27,I$27,FALSE)),"")>G42,G42,IFERROR(IF(VLOOKUP($F42,$F$4:$AP$27,I$27,FALSE)="","",VLOOKUP($F42,$F$4:$AP$27,I$27,FALSE)),"")) -> 40 | J42: =IFERROR(IF(VLOOKUP($F42,$F$4:$AP$27,J$27,FALSE)="","",VLOOKUP($F42,$F$4:$AP$27,J$27,FALSE)),"") -> 1.08 | K42: =IFERROR(IF(VLOOKUP($F42,$F$4:$AP$27,K$27,FALSE)="","",VLOOKUP($F42,$F$4:$AP$27,K$27,FALSE)),"") | L42: =IFERROR(IF(VLOOKUP($F42,$F$4:$AP$27,L$27,FALSE)="","",VLOOKUP($F42,$F$4:$AP$27,L$27,FALSE)),"") | M42: =IF(IFERROR(IF(VLOOKUP($F42,$F$4:$AP$27,M$27,FALSE)="","",VLOOKUP($F42,$F$4:$AP$27,M$27,FALSE)),"")>K42,K42,IFERROR(IF(VLOOKUP($F42,$F$4:$AP$27,M$27,FALSE)="","",VLOOKUP($F42,$F$4:$AP$27,M$27,FALSE)),"")) | N42: =IFERROR(IF(VLOOKUP($F42,$F$4:$AP$27,N$27,FALSE)="","",VLOOKUP($F42,$F$4:$AP$27,N$27,FALSE)),"") | O42: =IFERROR(IF(VLOOKUP($F42,$F$4:$AP$27,O$27,FALSE)="","",VLOOKUP($F42,$F$4:$AP$27,O$27,FALSE)),"") | P42: =IFERROR(IF(VLOOKUP($F42,$F$4:$AP$27,P$27,FALSE)="","",VLOOKUP($F42,$F$4:$AP$27,P$27,FALSE)),"") | Q42: =IFERROR(IF(VLOOKUP($F42,$F$4:$AP$27,Q$27,FALSE)="","",VLOOKUP($F42,$F$4:$AP$27,Q$27,FALSE)),"") | R42: =IFERROR(IF(VLOOKUP($F42,$F$4:$AP$27,R$27,FALSE)="","",VLOOKUP($F42,$F$4:$AP$27,R$27,FALSE)),"") | S42: =IFERROR(IF(VLOOKUP($F42,$F$4:$AP$27,S$27,FALSE)="","",VLOOKUP($F42,$F$4:$AP$27,S$27,FALSE)),"") | T42: =IFERROR(IF(VLOOKUP($F42,$F$4:$AP$27,T$27,FALSE)="","",VLOOKUP($F42,$F$4:$AP$27,T$27,FALSE)),"") | U42: =IFERROR(IF(VLOOKUP($F42,$F$4:$AP$27,U$27,FALSE)="","",VLOOKUP($F42,$F$4:$AP$27,U$27,FALSE)),"") | ... AP42: =IFERROR(IF(VLOOKUP($F42,$F$4:$AP$27,AP$27,FALSE)="","",VLOOKUP($F42,$F$4:$AP$27,AP$27,FALSE)),"")
A43: =IFERROR(G43/$G$25,"") | B43: =IFERROR( IF(SUM(H43:I43)/G43>1,1,SUM(H43:I43)/G43),"") | C43: =IFERROR(A43*B43,"") | D43: =IFERROR(A43-C43,"") | F43: 9600 | G43: =IFERROR(IF(VLOOKUP($F43,$F$4:$AP$27,G$27,FALSE)="","",VLOOKUP($F43,$F$4:$AP$27,G$27,FALSE)),"") | H43: =IFERROR(IF(VLOOKUP($F43,$F$4:$AP$27,H$27,FALSE)="","",VLOOKUP($F43,$F$4:$AP$27,H$27,FALSE)),"") | I43: =IF(IFERROR(IF(VLOOKUP($F43,$F$4:$AP$27,I$27,FALSE)="","",VLOOKUP($F43,$F$4:$AP$27,I$27,FALSE)),"")>G43,G43,IFERROR(IF(VLOOKUP($F43,$F$4:$AP$27,I$27,FALSE)="","",VLOOKUP($F43,$F$4:$AP$27,I$27,FALSE)),"")) | J43: =IFERROR(IF(VLOOKUP($F43,$F$4:$AP$27,J$27,FALSE)="","",VLOOKUP($F43,$F$4:$AP$27,J$27,FALSE)),"") | K43: =IFERROR(IF(VLOOKUP($F43,$F$4:$AP$27,K$27,FALSE)="","",VLOOKUP($F43,$F$4:$AP$27,K$27,FALSE)),"") | L43: =IFERROR(IF(VLOOKUP($F43,$F$4:$AP$27,L$27,FALSE)="","",VLOOKUP($F43,$F$4:$AP$27,L$27,FALSE)),"") | M43: =IF(IFERROR(IF(VLOOKUP($F43,$F$4:$AP$27,M$27,FALSE)="","",VLOOKUP($F43,$F$4:$AP$27,M$27,FALSE)),"")>K43,K43,IFERROR(IF(VLOOKUP($F43,$F$4:$AP$27,M$27,FALSE)="","",VLOOKUP($F43,$F$4:$AP$27,M$27,FALSE)),"")) | N43: =IFERROR(IF(VLOOKUP($F43,$F$4:$AP$27,N$27,FALSE)="","",VLOOKUP($F43,$F$4:$AP$27,N$27,FALSE)),"") | O43: =IFERROR(IF(VLOOKUP($F43,$F$4:$AP$27,O$27,FALSE)="","",VLOOKUP($F43,$F$4:$AP$27,O$27,FALSE)),"") | P43: =IFERROR(IF(VLOOKUP($F43,$F$4:$AP$27,P$27,FALSE)="","",VLOOKUP($F43,$F$4:$AP$27,P$27,FALSE)),"") | Q43: =IFERROR(IF(VLOOKUP($F43,$F$4:$AP$27,Q$27,FALSE)="","",VLOOKUP($F43,$F$4:$AP$27,Q$27,FALSE)),"") | S43: =IFERROR(IF(VLOOKUP($F43,$F$4:$AP$27,S$27,FALSE)="","",VLOOKUP($F43,$F$4:$AP$27,S$27,FALSE)),"") | T43: =IFERROR(IF(VLOOKUP($F43,$F$4:$AP$27,T$27,FALSE)="","",VLOOKUP($F43,$F$4:$AP$27,T$27,FALSE)),"") | U43: =IFERROR(IF(VLOOKUP($F43,$F$4:$AP$27,U$27,FALSE)="","",VLOOKUP($F43,$F$4:$AP$27,U$27,FALSE)),"") | V43: =IFERROR(IF(VLOOKUP($F43,$F$4:$AP$27,V$27,FALSE)="","",VLOOKUP($F43,$F$4:$AP$27,V$27,FALSE)),"") | W43: =IFERROR(IF(VLOOKUP($F43,$F$4:$AP$27,W$27,FALSE)="","",VLOOKUP($F43,$F$4:$AP$27,W$27,FALSE)),"") | X43: =IFERROR(IF(VLOOKUP($F43,$F$4:$AP$27,X$27,FALSE)="","",VLOOKUP($F43,$F$4:$AP$27,X$27,FALSE)),"") | Y43: =IFERROR(IF(VLOOKUP($F43,$F$4:$AP$27,Y$27,FALSE)="","",VLOOKUP($F43,$F$4:$AP$27,Y$27,FALSE)),"") | Z43: =IFERROR(IF(VLOOKUP($F43,$F$4:$AP$27,Z$27,FALSE)="","",VLOOKUP($F43,$F$4:$AP$27,Z$27,FALSE)),"") | ... AP43: =IFERROR(IF(VLOOKUP($F43,$F$4:$AP$27,AP$27,FALSE)="","",VLOOKUP($F43,$F$4:$AP$27,AP$27,FALSE)),"")
A44: =IFERROR(G44/$G$25,"") -> 0.13191489 | B44: =IFERROR( IF(SUM(H44:I44)/G44>1,1,SUM(H44:I44)/G44),"") -> 1 | C44: =IFERROR(A44*B44,"") -> 0.13191489 | D44: =IFERROR(A44-C44,"") -> 0 | E44: =VLOOKUP(_xlfn.NUMBERVALUE(F44),Sheet2!$A$1:$B$29,2,FALSE) -> Mimika | F44: 9601 | G44: =IFERROR(IF(VLOOKUP($F44,$F$4:$AP$27,G$27,FALSE)="","",VLOOKUP($F44,$F$4:$AP$27,G$27,FALSE)),"") -> 124 | H44: =IFERROR(IF(VLOOKUP($F44,$F$4:$AP$27,H$27,FALSE)="","",VLOOKUP($F44,$F$4:$AP$27,H$27,FALSE)),"") -> 0 | I44: =IF(IFERROR(IF(VLOOKUP($F44,$F$4:$AP$27,I$27,FALSE)="","",VLOOKUP($F44,$F$4:$AP$27,I$27,FALSE)),"")>G44,G44,IFERROR(IF(VLOOKUP($F44,$F$4:$AP$27,I$27,FALSE)="","",VLOOKUP($F44,$F$4:$AP$27,I$27,FALSE)),"")) -> 124 | J44: =IFERROR(IF(VLOOKUP($F44,$F$4:$AP$27,J$27,FALSE)="","",VLOOKUP($F44,$F$4:$AP$27,J$27,FALSE)),"") -> 1.01 | K44: =IFERROR(IF(VLOOKUP($F44,$F$4:$AP$27,K$27,FALSE)="","",VLOOKUP($F44,$F$4:$AP$27,K$27,FALSE)),"") -> 40 | L44: =IFERROR(IF(VLOOKUP($F44,$F$4:$AP$27,L$27,FALSE)="","",VLOOKUP($F44,$F$4:$AP$27,L$27,FALSE)),"") -> 0 | M44: =IF(IFERROR(IF(VLOOKUP($F44,$F$4:$AP$27,M$27,FALSE)="","",VLOOKUP($F44,$F$4:$AP$27,M$27,FALSE)),"")>K44,K44,IFERROR(IF(VLOOKUP($F44,$F$4:$AP$27,M$27,FALSE)="","",VLOOKUP($F44,$F$4:$AP$27,M$27,FALSE)),"")) -> 38 | N44: =IFERROR(IF(VLOOKUP($F44,$F$4:$AP$27,N$27,FALSE)="","",VLOOKUP($F44,$F$4:$AP$27,N$27,FALSE)),"") -> 0.95 | O44: =IFERROR(IF(VLOOKUP($F44,$F$4:$AP$27,O$27,FALSE)="","",VLOOKUP($F44,$F$4:$AP$27,O$27,FALSE)),"") | P44: =IFERROR(IF(VLOOKUP($F44,$F$4:$AP$27,P$27,FALSE)="","",VLOOKUP($F44,$F$4:$AP$27,P$27,FALSE)),"") | Q44: =IFERROR(IF(VLOOKUP($F44,$F$4:$AP$27,Q$27,FALSE)="","",VLOOKUP($F44,$F$4:$AP$27,Q$27,FALSE)),"") | R44: =IFERROR(IF(VLOOKUP($F44,$F$4:$AP$27,R$27,FALSE)="","",VLOOKUP($F44,$F$4:$AP$27,R$27,FALSE)),"") | S44: =IFERROR(IF(VLOOKUP($F44,$F$4:$AP$27,S$27,FALSE)="","",VLOOKUP($F44,$F$4:$AP$27,S$27,FALSE)),"") | T44: =IFERROR(IF(VLOOKUP($F44,$F$4:$AP$27,T$27,FALSE)="","",VLOOKUP($F44,$F$4:$AP$27,T$27,FALSE)),"") | U44: =IFERROR(IF(VLOOKUP($F44,$F$4:$AP$27,U$27,FALSE)="","",VLOOKUP($F44,$F$4:$AP$27,U$27,FALSE)),"") | ... AP44: =IFERROR(IF(VLOOKUP($F44,$F$4:$AP$27,AP$27,FALSE)="","",VLOOKUP($F44,$F$4:$AP$27,AP$27,FALSE)),"")
A45: =IFERROR(G45/$G$25,"") | B45: =IFERROR( IF(SUM(H45:I45)/G45>1,1,SUM(H45:I45)/G45),"") | C45: =IFERROR(A45*B45,"") | D45: =IFERROR(A45-C45,"") | E45: =VLOOKUP(_xlfn.NUMBERVALUE(F45),Sheet2!$A$1:$B$29,2,FALSE) -> Dogiyai | F45: 9602 | G45: =IFERROR(IF(VLOOKUP($F45,$F$4:$AP$27,G$27,FALSE)="","",VLOOKUP($F45,$F$4:$AP$27,G$27,FALSE)),"") | H45: =IFERROR(IF(VLOOKUP($F45,$F$4:$AP$27,H$27,FALSE)="","",VLOOKUP($F45,$F$4:$AP$27,H$27,FALSE)),"") | I45: =IF(IFERROR(IF(VLOOKUP($F45,$F$4:$AP$27,I$27,FALSE)="","",VLOOKUP($F45,$F$4:$AP$27,I$27,FALSE)),"")>G45,G45,IFERROR(IF(VLOOKUP($F45,$F$4:$AP$27,I$27,FALSE)="","",VLOOKUP($F45,$F$4:$AP$27,I$27,FALSE)),"")) | J45: =IFERROR(IF(VLOOKUP($F45,$F$4:$AP$27,J$27,FALSE)="","",VLOOKUP($F45,$F$4:$AP$27,J$27,FALSE)),"") | K45: =IFERROR(IF(VLOOKUP($F45,$F$4:$AP$27,K$27,FALSE)="","",VLOOKUP($F45,$F$4:$AP$27,K$27,FALSE)),"") | L45: =IFERROR(IF(VLOOKUP($F45,$F$4:$AP$27,L$27,FALSE)="","",VLOOKUP($F45,$F$4:$AP$27,L$27,FALSE)),"") | M45: =IF(IFERROR(IF(VLOOKUP($F45,$F$4:$AP$27,M$27,FALSE)="","",VLOOKUP($F45,$F$4:$AP$27,M$27,FALSE)),"")>K45,K45,IFERROR(IF(VLOOKUP($F45,$F$4:$AP$27,M$27,FALSE)="","",VLOOKUP($F45,$F$4:$AP$27,M$27,FALSE)),"")) | N45: =IFERROR(IF(VLOOKUP($F45,$F$4:$AP$27,N$27,FALSE)="","",VLOOKUP($F45,$F$4:$AP$27,N$27,FALSE)),"") | O45: =IFERROR(IF(VLOOKUP($F45,$F$4:$AP$27,O$27,FALSE)="","",VLOOKUP($F45,$F$4:$AP$27,O$27,FALSE)),"") | P45: =IFERROR(IF(VLOOKUP($F45,$F$4:$AP$27,P$27,FALSE)="","",VLOOKUP($F45,$F$4:$AP$27,P$27,FALSE)),"") | Q45: =IFERROR(IF(VLOOKUP($F45,$F$4:$AP$27,Q$27,FALSE)="","",VLOOKUP($F45,$F$4:$AP$27,Q$27,FALSE)),"") | R45: =IFERROR(IF(VLOOKUP($F45,$F$4:$AP$27,R$27,FALSE)="","",VLOOKUP($F45,$F$4:$AP$27,R$27,FALSE)),"") | S45: =IFERROR(IF(VLOOKUP($F45,$F$4:$AP$27,S$27,FALSE)="","",VLOOKUP($F45,$F$4:$AP$27,S$27,FALSE)),"") | T45: =IFERROR(IF(VLOOKUP($F45,$F$4:$AP$27,T$27,FALSE)="","",VLOOKUP($F45,$F$4:$AP$27,T$27,FALSE)),"") | U45: =IFERROR(IF(VLOOKUP($F45,$F$4:$AP$27,U$27,FALSE)="","",VLOOKUP($F45,$F$4:$AP$27,U$27,FALSE)),"") | ... AP45: =IFERROR(IF(VLOOKUP($F45,$F$4:$AP$27,AP$27,FALSE)="","",VLOOKUP($F45,$F$4:$AP$27,AP$27,FALSE)),"")
A46: =IFERROR(G46/$G$25,"") -> 0.028723404 | B46: =IFERROR( IF(SUM(H46:I46)/G46>1,1,SUM(H46:I46)/G46),"") -> 1 | C46: =IFERROR(A46*B46,"") -> 0.028723404 | D46: =IFERROR(A46-C46,"") -> 0 | E46: =VLOOKUP(_xlfn.NUMBERVALUE(F46),Sheet2!$A$1:$B$29,2,FALSE) -> Deiyai | F46: 9603 | G46: =IFERROR(IF(VLOOKUP($F46,$F$4:$AP$27,G$27,FALSE)="","",VLOOKUP($F46,$F$4:$AP$27,G$27,FALSE)),"") -> 27 | H46: =IFERROR(IF(VLOOKUP($F46,$F$4:$AP$27,H$27,FALSE)="","",VLOOKUP($F46,$F$4:$AP$27,H$27,FALSE)),"") -> 0 | I46: =IF(IFERROR(IF(VLOOKUP($F46,$F$4:$AP$27,I$27,FALSE)="","",VLOOKUP($F46,$F$4:$AP$27,I$27,FALSE)),"")>G46,G46,IFERROR(IF(VLOOKUP($F46,$F$4:$AP$27,I$27,FALSE)="","",VLOOKUP($F46,$F$4:$AP$27,I$27,FALSE)),"")) -> 27 | J46: =IFERROR(IF(VLOOKUP($F46,$F$4:$AP$27,J$27,FALSE)="","",VLOOKUP($F46,$F$4:$AP$27,J$27,FALSE)),"") -> 1 | K46: =IFERROR(IF(VLOOKUP($F46,$F$4:$AP$27,K$27,FALSE)="","",VLOOKUP($F46,$F$4:$AP$27,K$27,FALSE)),"") | L46: =IFERROR(IF(VLOOKUP($F46,$F$4:$AP$27,L$27,FALSE)="","",VLOOKUP($F46,$F$4:$AP$27,L$27,FALSE)),"") | M46: =IF(IFERROR(IF(VLOOKUP($F46,$F$4:$AP$27,M$27,FALSE)="","",VLOOKUP($F46,$F$4:$AP$27,M$27,FALSE)),"")>K46,K46,IFERROR(IF(VLOOKUP($F46,$F$4:$AP$27,M$27,FALSE)="","",VLOOKUP($F46,$F$4:$AP$27,M$27,FALSE)),"")) | N46: =IFERROR(IF(VLOOKUP($F46,$F$4:$AP$27,N$27,FALSE)="","",VLOOKUP($F46,$F$4:$AP$27,N$27,FALSE)),"") | O46: =IFERROR(IF(VLOOKUP($F46,$F$4:$AP$27,O$27,FALSE)="","",VLOOKUP($F46,$F$4:$AP$27,O$27,FALSE)),"") | P46: =IFERROR(IF(VLOOKUP($F46,$F$4:$AP$27,P$27,FALSE)="","",VLOOKUP($F46,$F$4:$AP$27,P$27,FALSE)),"") | Q46: =IFERROR(IF(VLOOKUP($F46,$F$4:$AP$27,Q$27,FALSE)="","",VLOOKUP($F46,$F$4:$AP$27,Q$27,FALSE)),"") | R46: =IFERROR(IF(VLOOKUP($F46,$F$4:$AP$27,R$27,FALSE)="","",VLOOKUP($F46,$F$4:$AP$27,R$27,FALSE)),"") | S46: =IFERROR(IF(VLOOKUP($F46,$F$4:$AP$27,S$27,FALSE)="","",VLOOKUP($F46,$F$4:$AP$27,S$27,FALSE)),"") | T46: =IFERROR(IF(VLOOKUP($F46,$F$4:$AP$27,T$27,FALSE)="","",VLOOKUP($F46,$F$4:$AP$27,T$27,FALSE)),"") | U46: =IFERROR(IF(VLOOKUP($F46,$F$4:$AP$27,U$27,FALSE)="","",VLOOKUP($F46,$F$4:$AP$27,U$27,FALSE)),"") | ... AP46: =IFERROR(IF(VLOOKUP($F46,$F$4:$AP$27,AP$27,FALSE)="","",VLOOKUP($F46,$F$4:$AP$27,AP$27,FALSE)),"")
A47: =IFERROR(G47/$G$25,"") -> 0.081914894 | B47: =IFERROR( IF(SUM(H47:I47)/G47>1,1,SUM(H47:I47)/G47),"") -> 1 | C47: =IFERROR(A47*B47,"") -> 0.081914894 | D47: =IFERROR(A47-C47,"") -> 0 | E47: =VLOOKUP(_xlfn.NUMBERVALUE(F47),Sheet2!$A$1:$B$29,2,FALSE) -> Nabire | F47: 9604 | G47: =IFERROR(IF(VLOOKUP($F47,$F$4:$AP$27,G$27,FALSE)="","",VLOOKUP($F47,$F$4:$AP$27,G$27,FALSE)),"") -> 77 | H47: =IFERROR(IF(VLOOKUP($F47,$F$4:$AP$27,H$27,FALSE)="","",VLOOKUP($F47,$F$4:$AP$27,H$27,FALSE)),"") -> 0 | I47: =IF(IFERROR(IF(VLOOKUP($F47,$F$4:$AP$27,I$27,FALSE)="","",VLOOKUP($F47,$F$4:$AP$27,I$27,FALSE)),"")>G47,G47,IFERROR(IF(VLOOKUP($F47,$F$4:$AP$27,I$27,FALSE)="","",VLOOKUP($F47,$F$4:$AP$27,I$27,FALSE)),"")) -> 77 | J47: =IFERROR(IF(VLOOKUP($F47,$F$4:$AP$27,J$27,FALSE)="","",VLOOKUP($F47,$F$4:$AP$27,J$27,FALSE)),"") -> 1.01 | K47: =IFERROR(IF(VLOOKUP($F47,$F$4:$AP$27,K$27,FALSE)="","",VLOOKUP($F47,$F$4:$AP$27,K$27,FALSE)),"") -> 2 | L47: =IFERROR(IF(VLOOKUP($F47,$F$4:$AP$27,L$27,FALSE)="","",VLOOKUP($F47,$F$4:$AP$27,L$27,FALSE)),"") -> 0 | M47: =IF(IFERROR(IF(VLOOKUP($F47,$F$4:$AP$27,M$27,FALSE)="","",VLOOKUP($F47,$F$4:$AP$27,M$27,FALSE)),"")>K47,K47,IFERROR(IF(VLOOKUP($F47,$F$4:$AP$27,M$27,FALSE)="","",VLOOKUP($F47,$F$4:$AP$27,M$27,FALSE)),"")) -> 2 | N47: =IFERROR(IF(VLOOKUP($F47,$F$4:$AP$27,N$27,FALSE)="","",VLOOKUP($F47,$F$4:$AP$27,N$27,FALSE)),"") -> 1 | O47: =IFERROR(IF(VLOOKUP($F47,$F$4:$AP$27,O$27,FALSE)="","",VLOOKUP($F47,$F$4:$AP$27,O$27,FALSE)),"") | P47: =IFERROR(IF(VLOOKUP($F47,$F$4:$AP$27,P$27,FALSE)="","",VLOOKUP($F47,$F$4:$AP$27,P$27,FALSE)),"") | Q47: =IFERROR(IF(VLOOKUP($F47,$F$4:$AP$27,Q$27,FALSE)="","",VLOOKUP($F47,$F$4:$AP$27,Q$27,FALSE)),"") | R47: =IFERROR(IF(VLOOKUP($F47,$F$4:$AP$27,R$27,FALSE)="","",VLOOKUP($F47,$F$4:$AP$27,R$27,FALSE)),"") | S47: =IFERROR(IF(VLOOKUP($F47,$F$4:$AP$27,S$27,FALSE)="","",VLOOKUP($F47,$F$4:$AP$27,S$27,FALSE)),"") | T47: =IFERROR(IF(VLOOKUP($F47,$F$4:$AP$27,T$27,FALSE)="","",VLOOKUP($F47,$F$4:$AP$27,T$27,FALSE)),"") | U47: =IFERROR(IF(VLOOKUP($F47,$F$4:$AP$27,U$27,FALSE)="","",VLOOKUP($F47,$F$4:$AP$27,U$27,FALSE)),"") | ... AP47: =IFERROR(IF(VLOOKUP($F47,$F$4:$AP$27,AP$27,FALSE)="","",VLOOKUP($F47,$F$4:$AP$27,AP$27,FALSE)),"")
A48: =IFERROR(G48/$G$25,"") | B48: =IFERROR( IF(SUM(H48:I48)/G48>1,1,SUM(H48:I48)/G48),"") | C48: =IFERROR(A48*B48,"") | D48: =IFERROR(A48-C48,"") | E48: =VLOOKUP(_xlfn.NUMBERVALUE(F48),Sheet2!$A$1:$B$29,2,FALSE) -> Paniai | F48: 9605 | G48: =IFERROR(IF(VLOOKUP($F48,$F$4:$AP$27,G$27,FALSE)="","",VLOOKUP($F48,$F$4:$AP$27,G$27,FALSE)),"") | H48: =IFERROR(IF(VLOOKUP($F48,$F$4:$AP$27,H$27,FALSE)="","",VLOOKUP($F48,$F$4:$AP$27,H$27,FALSE)),"") | I48: =IF(IFERROR(IF(VLOOKUP($F48,$F$4:$AP$27,I$27,FALSE)="","",VLOOKUP($F48,$F$4:$AP$27,I$27,FALSE)),"")>G48,G48,IFERROR(IF(VLOOKUP($F48,$F$4:$AP$27,I$27,FALSE)="","",VLOOKUP($F48,$F$4:$AP$27,I$27,FALSE)),"")) | J48: =IFERROR(IF(VLOOKUP($F48,$F$4:$AP$27,J$27,FALSE)="","",VLOOKUP($F48,$F$4:$AP$27,J$27,FALSE)),"") | K48: =IFERROR(IF(VLOOKUP($F48,$F$4:$AP$27,K$27,FALSE)="","",VLOOKUP($F48,$F$4:$AP$27,K$27,FALSE)),"") | L48: =IFERROR(IF(VLOOKUP($F48,$F$4:$AP$27,L$27,FALSE)="","",VLOOKUP($F48,$F$4:$AP$27,L$27,FALSE)),"") | M48: =IF(IFERROR(IF(VLOOKUP($F48,$F$4:$AP$27,M$27,FALSE)="","",VLOOKUP($F48,$F$4:$AP$27,M$27,FALSE)),"")>K48,K48,IFERROR(IF(VLOOKUP($F48,$F$4:$AP$27,M$27,FALSE)="","",VLOOKUP($F48,$F$4:$AP$27,M$27,FALSE)),"")) | N48: =IFERROR(IF(VLOOKUP($F48,$F$4:$AP$27,N$27,FALSE)="","",VLOOKUP($F48,$F$4:$AP$27,N$27,FALSE)),"") | O48: =IFERROR(IF(VLOOKUP($F48,$F$4:$AP$27,O$27,FALSE)="","",VLOOKUP($F48,$F$4:$AP$27,O$27,FALSE)),"") | P48: =IFERROR(IF(VLOOKUP($F48,$F$4:$AP$27,P$27,FALSE)="","",VLOOKUP($F48,$F$4:$AP$27,P$27,FALSE)),"") | Q48: =IFERROR(IF(VLOOKUP($F48,$F$4:$AP$27,Q$27,FALSE)="","",VLOOKUP($F48,$F$4:$AP$27,Q$27,FALSE)),"") | R48: =IFERROR(IF(VLOOKUP($F48,$F$4:$AP$27,R$27,FALSE)="","",VLOOKUP($F48,$F$4:$AP$27,R$27,FALSE)),"") | S48: =IFERROR(IF(VLOOKUP($F48,$F$4:$AP$27,S$27,FALSE)="","",VLOOKUP($F48,$F$4:$AP$27,S$27,FALSE)),"") | T48: =IFERROR(IF(VLOOKUP($F48,$F$4:$AP$27,T$27,FALSE)="","",VLOOKUP($F48,$F$4:$AP$27,T$27,FALSE)),"") | U48: =IFERROR(IF(VLOOKUP($F48,$F$4:$AP$27,U$27,FALSE)="","",VLOOKUP($F48,$F$4:$AP$27,U$27,FALSE)),"") | ... AP48: =IFERROR(IF(VLOOKUP($F48,$F$4:$AP$27,AP$27,FALSE)="","",VLOOKUP($F48,$F$4:$AP$27,AP$27,FALSE)),"")
A49: =IFERROR(G49/$G$25,"") | B49: =IFERROR( IF(SUM(H49:I49)/G49>1,1,SUM(H49:I49)/G49),"") | C49: =IFERROR(A49*B49,"") | D49: =IFERROR(A49-C49,"") | E49: =VLOOKUP(_xlfn.NUMBERVALUE(F49),Sheet2!$A$1:$B$29,2,FALSE) -> Intan Jaya | F49: 9606 | G49: =IFERROR(IF(VLOOKUP($F49,$F$4:$AP$27,G$27,FALSE)="","",VLOOKUP($F49,$F$4:$AP$27,G$27,FALSE)),"") | H49: =IFERROR(IF(VLOOKUP($F49,$F$4:$AP$27,H$27,FALSE)="","",VLOOKUP($F49,$F$4:$AP$27,H$27,FALSE)),"") | I49: =IF(IFERROR(IF(VLOOKUP($F49,$F$4:$AP$27,I$27,FALSE)="","",VLOOKUP($F49,$F$4:$AP$27,I$27,FALSE)),"")>G49,G49,IFERROR(IF(VLOOKUP($F49,$F$4:$AP$27,I$27,FALSE)="","",VLOOKUP($F49,$F$4:$AP$27,I$27,FALSE)),"")) | J49: =IFERROR(IF(VLOOKUP($F49,$F$4:$AP$27,J$27,FALSE)="","",VLOOKUP($F49,$F$4:$AP$27,J$27,FALSE)),"") | K49: =IFERROR(IF(VLOOKUP($F49,$F$4:$AP$27,K$27,FALSE)="","",VLOOKUP($F49,$F$4:$AP$27,K$27,FALSE)),"") | L49: =IFERROR(IF(VLOOKUP($F49,$F$4:$AP$27,L$27,FALSE)="","",VLOOKUP($F49,$F$4:$AP$27,L$27,FALSE)),"") | M49: =IF(IFERROR(IF(VLOOKUP($F49,$F$4:$AP$27,M$27,FALSE)="","",VLOOKUP($F49,$F$4:$AP$27,M$27,FALSE)),"")>K49,K49,IFERROR(IF(VLOOKUP($F49,$F$4:$AP$27,M$27,FALSE)="","",VLOOKUP($F49,$F$4:$AP$27,M$27,FALSE)),"")) | N49: =IFERROR(IF(VLOOKUP($F49,$F$4:$AP$27,N$27,FALSE)="","",VLOOKUP($F49,$F$4:$AP$27,N$27,FALSE)),"") | O49: =IFERROR(IF(VLOOKUP($F49,$F$4:$AP$27,O$27,FALSE)="","",VLOOKUP($F49,$F$4:$AP$27,O$27,FALSE)),"") | P49: =IFERROR(IF(VLOOKUP($F49,$F$4:$AP$27,P$27,FALSE)="","",VLOOKUP($F49,$F$4:$AP$27,P$27,FALSE)),"") | Q49: =IFERROR(IF(VLOOKUP($F49,$F$4:$AP$27,Q$27,FALSE)="","",VLOOKUP($F49,$F$4:$AP$27,Q$27,FALSE)),"") | R49: =IFERROR(IF(VLOOKUP($F49,$F$4:$AP$27,R$27,FALSE)="","",VLOOKUP($F49,$F$4:$AP$27,R$27,FALSE)),"") | S49: =IFERROR(IF(VLOOKUP($F49,$F$4:$AP$27,S$27,FALSE)="","",VLOOKUP($F49,$F$4:$AP$27,S$27,FALSE)),"") | T49: =IFERROR(IF(VLOOKUP($F49,$F$4:$AP$27,T$27,FALSE)="","",VLOOKUP($F49,$F$4:$AP$27,T$27,FALSE)),"") | U49: =IFERROR(IF(VLOOKUP($F49,$F$4:$AP$27,U$27,FALSE)="","",VLOOKUP($F49,$F$4:$AP$27,U$27,FALSE)),"") | ... AP49: =IFERROR(IF(VLOOKUP($F49,$F$4:$AP$27,AP$27,FALSE)="","",VLOOKUP($F49,$F$4:$AP$27,AP$27,FALSE)),"")
A50: =IFERROR(G50/$G$25,"") | B50: =IFERROR( IF(SUM(H50:I50)/G50>1,1,SUM(H50:I50)/G50),"") | C50: =IFERROR(A50*B50,"") | D50: =IFERROR(A50-C50,"") | E50: =VLOOKUP(_xlfn.NUMBERVALUE(F50),Sheet2!$A$1:$B$29,2,FALSE) -> Puncak | F50: 9607 | G50: =IFERROR(IF(VLOOKUP($F50,$F$4:$AP$27,G$27,FALSE)="","",VLOOKUP($F50,$F$4:$AP$27,G$27,FALSE)),"") | H50: =IFERROR(IF(VLOOKUP($F50,$F$4:$AP$27,H$27,FALSE)="","",VLOOKUP($F50,$F$4:$AP$27,H$27,FALSE)),"") | I50: =IF(IFERROR(IF(VLOOKUP($F50,$F$4:$AP$27,I$27,FALSE)="","",VLOOKUP($F50,$F$4:$AP$27,I$27,FALSE)),"")>G50,G50,IFERROR(IF(VLOOKUP($F50,$F$4:$AP$27,I$27,FALSE)="","",VLOOKUP($F50,$F$4:$AP$27,I$27,FALSE)),"")) | J50: =IFERROR(IF(VLOOKUP($F50,$F$4:$AP$27,J$27,FALSE)="","",VLOOKUP($F50,$F$4:$AP$27,J$27,FALSE)),"") | K50: =IFERROR(IF(VLOOKUP($F50,$F$4:$AP$27,K$27,FALSE)="","",VLOOKUP($F50,$F$4:$AP$27,K$27,FALSE)),"") | L50: =IFERROR(IF(VLOOKUP($F50,$F$4:$AP$27,L$27,FALSE)="","",VLOOKUP($F50,$F$4:$AP$27,L$27,FALSE)),"") | M50: =IF(IFERROR(IF(VLOOKUP($F50,$F$4:$AP$27,M$27,FALSE)="","",VLOOKUP($F50,$F$4:$AP$27,M$27,FALSE)),"")>K50,K50,IFERROR(IF(VLOOKUP($F50,$F$4:$AP$27,M$27,FALSE)="","",VLOOKUP($F50,$F$4:$AP$27,M$27,FALSE)),"")) | N50: =IFERROR(IF(VLOOKUP($F50,$F$4:$AP$27,N$27,FALSE)="","",VLOOKUP($F50,$F$4:$AP$27,N$27,FALSE)),"") | O50: =IFERROR(IF(VLOOKUP($F50,$F$4:$AP$27,O$27,FALSE)="","",VLOOKUP($F50,$F$4:$AP$27,O$27,FALSE)),"") | P50: =IFERROR(IF(VLOOKUP($F50,$F$4:$AP$27,P$27,FALSE)="","",VLOOKUP($F50,$F$4:$AP$27,P$27,FALSE)),"") | Q50: =IFERROR(IF(VLOOKUP($F50,$F$4:$AP$27,Q$27,FALSE)="","",VLOOKUP($F50,$F$4:$AP$27,Q$27,FALSE)),"") | R50: =IFERROR(IF(VLOOKUP($F50,$F$4:$AP$27,R$27,FALSE)="","",VLOOKUP($F50,$F$4:$AP$27,R$27,FALSE)),"") | S50: =IFERROR(IF(VLOOKUP($F50,$F$4:$AP$27,S$27,FALSE)="","",VLOOKUP($F50,$F$4:$AP$27,S$27,FALSE)),"") | T50: =IFERROR(IF(VLOOKUP($F50,$F$4:$AP$27,T$27,FALSE)="","",VLOOKUP($F50,$F$4:$AP$27,T$27,FALSE)),"") | U50: =IFERROR(IF(VLOOKUP($F50,$F$4:$AP$27,U$27,FALSE)="","",VLOOKUP($F50,$F$4:$AP$27,U$27,FALSE)),"") | ... AP50: =IFERROR(IF(VLOOKUP($F50,$F$4:$AP$27,AP$27,FALSE)="","",VLOOKUP($F50,$F$4:$AP$27,AP$27,FALSE)),"")
...

Sheet imk tahunan
A1: weights | B1: % lapangan | C1: %lapangan_weighted | D1: total_belum | E1: kota | F1: kab_id | G1: total
